Workbook

Sheet Sheet1
A2: Dates | B2: Holiday | D2: Months | E2: Year
A3: 45658 | B3: New Year | D3: Jan | E3: 2025
A4: 45683 | B4: Republic Day | D4: Feb | E4: 2026
A5: 45724 | B5: Holi | D5: Mar | E5: 2027
A6: 45754 | B6: Good Friday | D6: Apr | E6: 2028
A7: 45778 | B7: Labour Day | D7: May | E7: 2029
A8: 45837 | B8: Bakrid | D8: Jun | E8: 2030
A9: 45867 | B9: Muharram | D9: Jul | E9: 2031
A10: 45884 | B10: Independence Day | D10: Aug | E10: 2032
A11: 45899 | B11: Raksha Bandhan | D11: Sep | E11: 2033
A12: 45919 | B12: Ganesh Chaturthi | D12: Oct | E12: 2034
A13: 45928 | B13: Eid Milad | D13: Nov | E13: 2035
A14: 45932 | B14: Gandhi Jayanti | D14: Dec | E14: 2036
A15: 45953 | B15: Ayudha Pooja | D15: Yearly | E15: 2036
A16: 45954 | B16: Vijay Dashmi
A17: 45974 | B17: Diwali
A18: 45988 | B18: Guru Nanak Jayanti
A19: 46016 | B19: Christmas

Sheet Jan
B2: Summary
G3: Daily Sales Report | T3: Consolidated
C4: Month | D4: Jan | G4: Sr No. | H4: Date | I4: Day | J4: Holidays | K4: Dine in Sales | L4: Dine in Tkts. | M4: APC/APT(Avg. /Transaction) | N4: TA Sales | O4: TA Tkts. | P4: APC/APT(Avg. /Transaction) | Q4: Delivery Sales | R4: Delivery Tkts. | S4: APC/APT(Avg. /Transaction) | T4: Target Sales | U4: Total Sales | V4: Total Tkts. | W4: APC/APT | X4: Target vs Acheived | Y4: %
G5: 1 | H5: =D8 -> 45658 | I5: =TEXT(H5,"DDD") -> Wed | J5: =IFERROR(VLOOKUP(H5,Sheet1!$A:$B,2,0),"") -> New Year | P5: =IFERROR(IF(N5=0,"",N5/O5),"") | S5: =IFERROR(IF(Q5=0,"",Q5/R5),"") | U5: =K5+N5+Q5 -> 0 | V5: =L5+O5+R5 -> 0 | W5: =IFERROR(U5/V5,"0") -> 0 | X5: =U5-T5 -> 0 | Y5: =IFERROR(U5/T5,"0") -> 0
C6: Year | D6: 2025 | G6: 2 | H6: =IF(H5<$D$10,H5+1,"") -> 45659 | I6: =TEXT(H6,"DDD") -> Thu | J6: =IFERROR(VLOOKUP(H6,Sheet1!$A:$B,2,0),"") | M6: =IFERROR(IF(K6=0,"",K6/L6),"") | P6: =IFERROR(IF(N6=0,"",N6/O6),"") | S6: =IFERROR(IF(Q6=0,"",Q6/R6),"") | U6: =K6+N6+Q6 -> 0 | V6: =L6+O6+R6 -> 0 | W6: =IFERROR(U6/V6,"0") -> 0 | X6: =U6-T6 -> 0 | Y6: =IFERROR(U6/T6,"0") -> 0
G7: 3 | H7: =IF(H6<$D$10,H6+1,"") -> 45660 | I7: =TEXT(H7,"DDD") -> Fri | J7: =IFERROR(VLOOKUP(H7,Sheet1!$A:$B,2,0),"") | M7: =IFERROR(IF(K7=0,"",K7/L7),"") | P7: =IFERROR(IF(N7=0,"",N7/O7),"") | S7: =IFERROR(IF(Q7=0,"",Q7/R7),"") | U7: =K7+N7+Q7 -> 0 | V7: =L7+O7+R7 -> 0 | W7: =IFERROR(U7/V7,"0") -> 0 | X7: =U7-T7 -> 0 | Y7: =IFERROR(U7/T7,"0") -> 0
C8: Start Date | D8: =DATEVALUE("01"&D4&D6) -> 45658 | G8: 4 | H8: =IF(H7<$D$10,H7+1,"") -> 45661 | I8: =TEXT(H8,"DDD") -> Sat | J8: =IFERROR(VLOOKUP(H8,Sheet1!$A:$B,2,0),"") | M8: =IFERROR(IF(K8=0,"",K8/L8),"") | P8: =IFERROR(IF(N8=0,"",N8/O8),"") | S8: =IFERROR(IF(Q8=0,"",Q8/R8),"") | U8: =K8+N8+Q8 -> 0 | V8: =L8+O8+R8 -> 0 | W8: =IFERROR(U8/V8,"0") -> 0 | X8: =U8-T8 -> 0 | Y8: =IFERROR(U8/T8,"0") -> 0
G9: 5 | H9: =IF(H8<$D$10,H8+1,"") -> 45662 | I9: =TEXT(H9,"DDD") -> Sun | J9: =IFERROR(VLOOKUP(H9,Sheet1!$A:$B,2,0),"") | M9: =IFERROR(IF(K9=0,"",K9/L9),"") | P9: =IFERROR(IF(N9=0,"",N9/O9),"") | S9: =IFERROR(IF(Q9=0,"",Q9/R9),"") | U9: =K9+N9+Q9 -> 0 | V9: =L9+O9+R9 -> 0 | W9: =IFERROR(U9/V9,"0") -> 0 | X9: =U9-T9 -> 0 | Y9: =IFERROR(U9/T9,"0") -> 0
C10: End Date | D10: =EOMONTH(D8,0) -> 45688 | G10: 6 | H10: =IF(H9<$D$10,H9+1,"") -> 45663 | I10: =TEXT(H10,"DDD") -> Mon | J10: =IFERROR(VLOOKUP(H10,Sheet1!$A:$B,2,0),"") | M10: =IFERROR(IF(K10=0,"",K10/L10),"") | P10: =IFERROR(IF(N10=0,"",N10/O10),"") | S10: =IFERROR(IF(Q10=0,"",Q10/R10),"") | U10: =K10+N10+Q10 -> 0 | V10: =L10+O10+R10 -> 0 | W10: =IFERROR(U10/V10,"0") -> 0 | X10: =U10-T10 -> 0 | Y10: =IFERROR(U10/T10,"0") -> 0
G11: 7 | H11: =IF(H10<$D$10,H10+1,"") -> 45664 | I11: =TEXT(H11,"DDD") -> Tue | J11: =IFERROR(VLOOKUP(H11,Sheet1!$A:$B,2,0),"") | M11: =IFERROR(IF(K11=0,"",K11/L11),"") | P11: =IFERROR(IF(N11=0,"",N11/O11),"") | S11: =IFERROR(IF(Q11=0,"",Q11/R11),"") | U11: =K11+N11+Q11 -> 0 | V11: =L11+O11+R11 -> 0 | W11: =IFERROR(U11/V11,"0") -> 0 | X11: =U11-T11 -> 0 | Y11: =IFERROR(U11/T11,"0") -> 0
C12: Total Days | D12: =COUNT(H5:H35) -> 31 | G12: 8 | H12: =IF(H11<$D$10,H11+1,"") -> 45665 | I12: =TEXT(H12,"DDD") -> Wed | J12: =IFERROR(VLOOKUP(H12,Sheet1!$A:$B,2,0),"") | M12: =IFERROR(IF(K12=0,"",K12/L12),"") | P12: =IFERROR(IF(N12=0,"",N12/O12),"") | S12: =IFERROR(IF(Q12=0,"",Q12/R12),"") | U12: =K12+N12+Q12 -> 0 | V12: =L12+O12+R12 -> 0 | W12: =IFERROR(U12/V12,"0") -> 0 | X12: =U12-T12 -> 0 | Y12: =IFERROR(U12/T12,"0") -> 0
G13: 9 | H13: =IF(H12<$D$10,H12+1,"") -> 45666 | I13: =TEXT(H13,"DDD") -> Thu | J13: =IFERROR(VLOOKUP(H13,Sheet1!$A:$B,2,0),"") | M13: =IFERROR(IF(K13=0,"",K13/L13),"") | P13: =IFERROR(IF(N13=0,"",N13/O13),"") | S13: =IFERROR(IF(Q13=0,"",Q13/R13),"") | U13: =K13+N13+Q13 -> 0 | V13: =L13+O13+R13 -> 0 | W13: =IFERROR(U13/V13,"0") -> 0 | X13: =U13-T13 -> 0 | Y13: =IFERROR(U13/T13,"0") -> 0
C14: Total Sat | D14: =COUNTIF(I5:I35,"Sat") -> 4 | G14: 10 | H14: =IF(H13<$D$10,H13+1,"") -> 45667 | I14: =TEXT(H14,"DDD") -> Fri | J14: =IFERROR(VLOOKUP(H14,Sheet1!$A:$B,2,0),"") | M14: =IFERROR(IF(K14=0,"",K14/L14),"") | P14: =IFERROR(IF(N14=0,"",N14/O14),"") | S14: =IFERROR(IF(Q14=0,"",Q14/R14),"") | U14: =K14+N14+Q14 -> 0 | V14: =L14+O14+R14 -> 0 | W14: =IFERROR(U14/V14,"0") -> 0 | X14: =U14-T14 -> 0 | Y14: =IFERROR(U14/T14,"0") -> 0
C15: Total Sun | D15: =COUNTIF(I5:I35,"Sun") -> 4 | G15: 11 | H15: =IF(H14<$D$10,H14+1,"") -> 45668 | I15: =TEXT(H15,"DDD") -> Sat | J15: =IFERROR(VLOOKUP(H15,Sheet1!$A:$B,2,0),"") | M15: =IFERROR(IF(K15=0,"",K15/L15),"") | P15: =IFERROR(IF(N15=0,"",N15/O15),"") | S15: =IFERROR(IF(Q15=0,"",Q15/R15),"") | U15: =K15+N15+Q15 -> 0 | V15: =L15+O15+R15 -> 0 | W15: =IFERROR(U15/V15,"0") -> 0 | X15: =U15-T15 -> 0 | Y15: =IFERROR(U15/T15,"0") -> 0
G16: 12 | H16: =IF(H15<$D$10,H15+1,"") -> 45669 | I16: =TEXT(H16,"DDD") -> Sun | J16: =IFERROR(VLOOKUP(H16,Sheet1!$A:$B,2,0),"") | M16: =IFERROR(IF(K16=0,"",K16/L16),"") | P16: =IFERROR(IF(N16=0,"",N16/O16),"") | S16: =IFERROR(IF(Q16=0,"",Q16/R16),"") | U16: =K16+N16+Q16 -> 0 | V16: =L16+O16+R16 -> 0 | W16: =IFERROR(U16/V16,"0") -> 0 | X16: =U16-T16 -> 0 | Y16: =IFERROR(U16/T16,"0") -> 0
C17: Highest Sale for the month | D17: =MAX(U5:U35) -> 0 | G17: 13 | H17: =IF(H16<$D$10,H16+1,"") -> 45670 | I17: =TEXT(H17,"DDD") -> Mon | J17: =IFERROR(VLOOKUP(H17,Sheet1!$A:$B,2,0),"") | M17: =IFERROR(IF(K17=0,"",K17/L17),"") | P17: =IFERROR(IF(N17=0,"",N17/O17),"") | S17: =IFERROR(IF(Q17=0,"",Q17/R17),"") | U17: =K17+N17+Q17 -> 0 | V17: =L17+O17+R17 -> 0 | W17: =IFERROR(U17/V17,"0") -> 0 | X17: =U17-T17 -> 0 | Y17: =IFERROR(U17/T17,"0") -> 0
G18: 14 | H18: =IF(H17<$D$10,H17+1,"") -> 45671 | I18: =TEXT(H18,"DDD") -> Tue | J18: =IFERROR(VLOOKUP(H18,Sheet1!$A:$B,2,0),"") | M18: =IFERROR(IF(K18=0,"",K18/L18),"") | P18: =IFERROR(IF(N18=0,"",N18/O18),"") | S18: =IFERROR(IF(Q18=0,"",Q18/R18),"") | U18: =K18+N18+Q18 -> 0 | V18: =L18+O18+R18 -> 0 | W18: =IFERROR(U18/V18,"0") -> 0 | X18: =U18-T18 -> 0 | Y18: =IFERROR(U18/T18,"0") -> 0
G19: 15 | H19: =IF(H18<$D$10,H18+1,"") -> 45672 | I19: =TEXT(H19,"DDD") -> Wed | J19: =IFERROR(VLOOKUP(H19,Sheet1!$A:$B,2,0),"") | M19: =IFERROR(IF(K19=0,"",K19/L19),"") | P19: =IFERROR(IF(N19=0,"",N19/O19),"") | S19: =IFERROR(IF(Q19=0,"",Q19/R19),"") | U19: =K19+N19+Q19 -> 0 | V19: =L19+O19+R19 -> 0 | W19: =IFERROR(U19/V19,"0") -> 0 | X19: =U19-T19 -> 0 | Y19: =IFERROR(U19/T19,"0") -> 0
C20: Lowest Sale for the month | D20: =MIN(U8:U38) -> 0 | G20: 16 | H20: =IF(H19<$D$10,H19+1,"") -> 45673 | I20: =TEXT(H20,"DDD") -> Thu | J20: =IFERROR(VLOOKUP(H20,Sheet1!$A:$B,2,0),"") | M20: =IFERROR(IF(K20=0,"",K20/L20),"") | P20: =IFERROR(IF(N20=0,"",N20/O20),"") | S20: =IFERROR(IF(Q20=0,"",Q20/R20),"") | U20: =K20+N20+Q20 -> 0 | V20: =L20+O20+R20 -> 0 | W20: =IFERROR(U20/V20,"0") -> 0 | X20: =U20-T20 -> 0 | Y20: =IFERROR(U20/T20,"0") -> 0
G21: 17 | H21: =IF(H20<$D$10,H20+1,"") -> 45674 | I21: =TEXT(H21,"DDD") -> Fri | J21: =IFERROR(VLOOKUP(H21,Sheet1!$A:$B,2,0),"") | M21: =IFERROR(IF(K21=0,"",K21/L21),"") | P21: =IFERROR(IF(N21=0,"",N21/O21),"") | S21: =IFERROR(IF(Q21=0,"",Q21/R21),"") | U21: =K21+N21+Q21 -> 0 | V21: =L21+O21+R21 -> 0 | W21: =IFERROR(U21/V21,"0") -> 0 | X21: =U21-T21 -> 0 | Y21: =IFERROR(U21/T21,"0") -> 0
G22: 18 | H22: =IF(H21<$D$10,H21+1,"") -> 45675 | I22: =TEXT(H22,"DDD") -> Sat | J22: =IFERROR(VLOOKUP(H22,Sheet1!$A:$B,2,0),"") | M22: =IFERROR(IF(K22=0,"",K22/L22),"") | P22: =IFERROR(IF(N22=0,"",N22/O22),"") | S22: =IFERROR(IF(Q22=0,"",Q22/R22),"") | U22: =K22+N22+Q22 -> 0 | V22: =L22+O22+R22 -> 0 | W22: =IFERROR(U22/V22,"0") -> 0 | X22: =U22-T22 -> 0 | Y22: =IFERROR(U22/T22,"0") -> 0
C23: Target Achieved | D23: =IF(U36>T36,"Yes","No") -> No | G23: 19 | H23: =IF(H22<$D$10,H22+1,"") -> 45676 | I23: =TEXT(H23,"DDD") -> Sun | J23: =IFERROR(VLOOKUP(H23,Sheet1!$A:$B,2,0),"") | M23: =IFERROR(IF(K23=0,"",K23/L23),"") | P23: =IFERROR(IF(N23=0,"",N23/O23),"") | S23: =IFERROR(IF(Q23=0,"",Q23/R23),"") | U23: =K23+N23+Q23 -> 0 | V23: =L23+O23+R23 -> 0 | W23: =IFERROR(U23/V23,"0") -> 0 | X23: =U23-T23 -> 0 | Y23: =IFERROR(U23/T23,"0") -> 0
G24: 20 | H24: =IF(H23<$D$10,H23+1,"") -> 45677 | I24: =TEXT(H24,"DDD") -> Mon | J24: =IFERROR(VLOOKUP(H24,Sheet1!$A:$B,2,0),"") | M24: =IFERROR(IF(K24=0,"",K24/L24),"") | P24: =IFERROR(IF(N24=0,"",N24/O24),"") | S24: =IFERROR(IF(Q24=0,"",Q24/R24),"") | U24: =K24+N24+Q24 -> 0 | V24: =L24+O24+R24 -> 0 | W24: =IFERROR(U24/V24,"0") -> 0 | X24: =U24-T24 -> 0 | Y24: =IFERROR(U24/T24,"0") -> 0
C25: Sales Till Date | D25: =U36 -> 0 | G25: 21 | H25: =IF(H24<$D$10,H24+1,"") -> 45678 | I25: =TEXT(H25,"DDD") -> Tue | J25: =IFERROR(VLOOKUP(H25,Sheet1!$A:$B,2,0),"") | M25: =IFERROR(IF(K25=0,"",K25/L25),"") | P25: =IFERROR(IF(N25=0,"",N25/O25),"") | S25: =IFERROR(IF(Q25=0,"",Q25/R25),"") | U25: =K25+N25+Q25 -> 0 | V25: =L25+O25+R25 -> 0 | W25: =IFERROR(U25/V25,"0") -> 0 | X25: =U25-T25 -> 0 | Y25: =IFERROR(U25/T25,"0") -> 0
G26: 22 | H26: =IF(H25<$D$10,H25+1,"") -> 45679 | I26: =TEXT(H26,"DDD") -> Wed | J26: =IFERROR(VLOOKUP(H26,Sheet1!$A:$B,2,0),"") | M26: =IFERROR(IF(K26=0,"",K26/L26),"") | P26: =IFERROR(IF(N26=0,"",N26/O26),"") | S26: =IFERROR(IF(Q26=0,"",Q26/R26),"") | U26: =K26+N26+Q26 -> 0 | V26: =L26+O26+R26 -> 0 | W26: =IFERROR(U26/V26,"0") -> 0 | X26: =U26-T26 -> 0 | Y26: =IFERROR(U26/T26,"0") -> 0
C27: Average Sales | D27: =IFERROR(AVERAGE(U5:U35),"0") -> 0 | G27: 23 | H27: =IF(H26<$D$10,H26+1,"") -> 45680 | I27: =TEXT(H27,"DDD") -> Thu | J27: =IFERROR(VLOOKUP(H27,Sheet1!$A:$B,2,0),"") | M27: =IFERROR(IF(K27=0,"",K27/L27),"") | P27: =IFERROR(IF(N27=0,"",N27/O27),"") | S27: =IFERROR(IF(Q27=0,"",Q27/R27),"") | U27: =K27+N27+Q27 -> 0 | V27: =L27+O27+R27 -> 0 | W27: =IFERROR(U27/V27,"0") -> 0 | X27: =U27-T27 -> 0 | Y27: =IFERROR(U27/T27,"0") -> 0
C28: Dine in Sales | D28: =K36 -> 0 | G28: 24 | H28: =IF(H27<$D$10,H27+1,"") -> 45681 | I28: =TEXT(H28,"DDD") -> Fri | J28: =IFERROR(VLOOKUP(H28,Sheet1!$A:$B,2,0),"") | M28: =IFERROR(IF(K28=0,"",K28/L28),"") | P28: =IFERROR(IF(N28=0,"",N28/O28),"") | S28: =IFERROR(IF(Q28=0,"",Q28/R28),"") | U28: =K28+N28+Q28 -> 0 | V28: =L28+O28+R28 -> 0 | W28: =IFERROR(U28/V28,"0") -> 0 | X28: =U28-T28 -> 0 | Y28: =IFERROR(U28/T28,"0") -> 0
C29: Takeaway Sales | D29: =N36 -> 0 | G29: 25 | H29: =IF(H28<$D$10,H28+1,"") -> 45682 | I29: =TEXT(H29,"DDD") -> Sat | J29: =IFERROR(VLOOKUP(H29,Sheet1!$A:$B,2,0),"") | M29: =IFERROR(IF(K29=0,"",K29/L29),"") | P29: =IFERROR(IF(N29=0,"",N29/O29),"") | S29: =IFERROR(IF(Q29=0,"",Q29/R29),"") | U29: =K29+N29+Q29 -> 0 | V29: =L29+O29+R29 -> 0 | W29: =IFERROR(U29/V29,"0") -> 0 | X29: =U29-T29 -> 0 | Y29: =IFERROR(U29/T29,"0") -> 0
C30: Delivery Sales | D30: =Q36 -> 0 | G30: 26 | H30: =IF(H29<$D$10,H29+1,"") -> 45683 | I30: =TEXT(H30,"DDD") -> Sun | J30: =IFERROR(VLOOKUP(H30,Sheet1!$A:$B,2,0),"") -> Republic Day | M30: =IFERROR(IF(K30=0,"",K30/L30),"") | P30: =IFERROR(IF(N30=0,"",N30/O30),"") | S30: =IFERROR(IF(Q30=0,"",Q30/R30),"") | U30: =K30+N30+Q30 -> 0 | V30: =L30+O30+R30 -> 0 | W30: =IFERROR(U30/V30,"0") -> 0 | X30: =U30-T30 -> 0 | Y30: =IFERROR(U30/T30,"0") -> 0
G31: 27 | H31: =IF(H30<$D$10,H30+1,"") -> 45684 | I31: =TEXT(H31,"DDD") -> Mon | J31: =IFERROR(VLOOKUP(H31,Sheet1!$A:$B,2,0),"") | M31: =IFERROR(IF(K31=0,"",K31/L31),"") | P31: =IFERROR(IF(N31=0,"",N31/O31),"") | S31: =IFERROR(IF(Q31=0,"",Q31/R31),"") | U31: =K31+N31+Q31 -> 0 | V31: =L31+O31+R31 -> 0 | W31: =IFERROR(U31/V31,"0") -> 0 | X31: =U31-T31 -> 0 | Y31: =IFERROR(U31/T31,"0") -> 0
C32: Total Sales | D32: =SUM(D28:D30) -> 0 | G32: 28 | H32: =IF(H31<$D$10,H31+1,"") -> 45685 | I32: =TEXT(H32,"DDD") -> Tue | J32: =IFERROR(VLOOKUP(H32,Sheet1!$A:$B,2,0),"") | M32: =IFERROR(IF(K32=0,"",K32/L32),"") | P32: =IFERROR(IF(N32=0,"",N32/O32),"") | S32: =IFERROR(IF(Q32=0,"",Q32/R32),"") | U32: =K32+N32+Q32 -> 0 | V32: =L32+O32+R32 -> 0 | W32: =IFERROR(U32/V32,"0") -> 0 | X32: =U32-T32 -> 0 | Y32: =IFERROR(U32/T32,"0") -> 0
C33: Last year sales | D33: 5000 | G33: 29 | H33: =IF(H32<$D$10,H32+1,"") -> 45686 | I33: =TEXT(H33,"DDD") -> Wed | J33: =IFERROR(VLOOKUP(H33,Sheet1!$A:$B,2,0),"") | M33: =IFERROR(IF(K33=0,"",K33/L33),"") | P33: =IFERROR(IF(N33=0,"",N33/O33),"") | S33: =IFERROR(IF(Q33=0,"",Q33/R33),"") | U33: =K33+N33+Q33 -> 0 | V33: =L33+O33+R33 -> 0 | W33: =IFERROR(U33/V33,"0") -> 0 | X33: =U33-T33 -> 0 | Y33: =IFERROR(U33/T33,"0") -> 0
C34: Growth | D34: =D32-D33 -> -5000 | G34: 30 | H34: =IF(H33<$D$10,H33+1,"") -> 45687 | I34: =TEXT(H34,"DDD") -> Thu | J34: =IFERROR(VLOOKUP(H34,Sheet1!$A:$B,2,0),"") | M34: =IFERROR(IF(K34=0,"",K34/L34),"") | P34: =IFERROR(IF(N34=0,"",N34/O34),"") | S34: =IFERROR(IF(Q34=0,"",Q34/R34),"") | U34: =K34+N34+Q34 -> 0 | V34: =L34+O34+R34 -> 0 | W34: =IFERROR(U34/V34,"0") -> 0 | X34: =U34-T34 -> 0 | Y34: =IFERROR(U34/T34,"0") -> 0
C35: Growth % | D35: =IFERROR((D32-D33)/D33,"0") -> -1 | G35: 31 | H35: =IF(H34<$D$10,H34+1,"") -> 45688 | I35: =TEXT(H35,"DDD") -> Fri | J35: =IFERROR(VLOOKUP(H35,Sheet1!$A:$B,2,0),"") | M35: =IFERROR(IF(K35=0,"",K35/L35),"") | P35: =IFERROR(IF(N35=0,"",N35/O35),"") | S35: =IFERROR(IF(Q35=0,"",Q35/R35),"") | U35: =K35+N35+Q35 -> 0 | V35: =L35+O35+R35 -> 0 | W35: =IFERROR(U35/V35,"0") -> 0 | X35: =U35-T35 -> 0 | Y35: =IFERROR(U35/T35,"0") -> 0
G36: Total | K36: =SUM(K5:K35) -> 0 | L36: =SUM(L5:L35) -> 0 | M36: =IFERROR(K36/L36,"0") -> 0 | N36: =SUM(N5:N35) -> 0 | O36: =SUM(O5:O35) -> 0 | P36: =IFERROR(N36/O36,"0") -> 0 | Q36: =SUM(Q5:Q35) -> 0 | R36: =SUM(R5:R35) -> 0 | S36: =IFERROR(Q36/R36,"0") -> 0 | T36: =SUM(T5:T35) -> 0 | U36: =SUM(U5:U35) -> 0 | V36: =SUM(V5:V35) -> 0 | W36: =IFERROR(U36/V36,"0") -> 0 | X36: =SUM(X5:X35) -> 0 | Y36: =SUM(Y5:Y35) -> 0

Sheet Feb
B2: Summary
G3: Daily Sales Report | T3: Consolidated
C4: Month | D4: Feb | G4: Sr No. | H4: Date | I4: Day | J4: Holidays | K4: Dine in Sales | L4: Dine in Tkts. | M4: APC/APT(Avg. /Transaction) | N4: TA Sales | O4: TA Tkts. | P4: APC/APT(Avg. /Transaction) | Q4: Delivery Sales | R4: Delivery Tkts. | S4: APC/APT(Avg. /Transaction) | T4: Target Sales | U4: Total Sales | V4: Total Tkts. | W4: APC/APT | X4: Target vs Acheived | Y4: %
G5: 1 | H5: =D8 -> 45689 | I5: =TEXT(H5,"DDD") -> Sat | J5: =IFERROR(VLOOKUP(H5,Sheet1!$A:$B,2,0),"") | M5: =IFERROR(IF(K5=0,"",K5/L5),"") | P5: =IFERROR(IF(N5=0,"",N5/O5),"") | S5: =IFERROR(IF(Q5=0,"",Q5/R5),"") | U5: =K5+N5+Q5 -> 0 | V5: =L5+O5+R5 -> 0 | W5: =IFERROR(U5/V5,"0") -> 0 | X5: =U5-T5 -> 0 | Y5: =IFERROR(U5/T5,"0") -> 0
C6: Year | D6: 2025 | G6: 2 | H6: =IF(H5<$D$10,H5+1,"") -> 45690 | I6: =TEXT(H6,"DDD") -> Sun | J6: =IFERROR(VLOOKUP(H6,Sheet1!$A:$B,2,0),"") | M6: =IFERROR(IF(K6=0,"",K6/L6),"") | P6: =IFERROR(IF(N6=0,"",N6/O6),"") | S6: =IFERROR(IF(Q6=0,"",Q6/R6),"") | U6: =K6+N6+Q6 -> 0 | V6: =L6+O6+R6 -> 0 | W6: =IFERROR(U6/V6,"0") -> 0 | X6: =U6-T6 -> 0 | Y6: =IFERROR(U6/T6,"0") -> 0
G7: 3 | H7: =IF(H6<$D$10,H6+1,"") -> 45691 | I7: =TEXT(H7,"DDD") -> Mon | J7: =IFERROR(VLOOKUP(H7,Sheet1!$A:$B,2,0),"") | M7: =IFERROR(IF(K7=0,"",K7/L7),"") | P7: =IFERROR(IF(N7=0,"",N7/O7),"") | S7: =IFERROR(IF(Q7=0,"",Q7/R7),"") | U7: =K7+N7+Q7 -> 0 | V7: =L7+O7+R7 -> 0 | W7: =IFERROR(U7/V7,"0") -> 0 | X7: =U7-T7 -> 0 | Y7: =IFERROR(U7/T7,"0") -> 0
C8: Start Date | D8: =DATEVALUE("01"&D4&D6) -> 45689 | G8: 4 | H8: =IF(H7<$D$10,H7+1,"") -> 45692 | I8: =TEXT(H8,"DDD") -> Tue | J8: =IFERROR(VLOOKUP(H8,Sheet1!$A:$B,2,0),"") | M8: =IFERROR(IF(K8=0,"",K8/L8),"") | P8: =IFERROR(IF(N8=0,"",N8/O8),"") | S8: =IFERROR(IF(Q8=0,"",Q8/R8),"") | U8: =K8+N8+Q8 -> 0 | V8: =L8+O8+R8 -> 0 | W8: =IFERROR(U8/V8,"0") -> 0 | X8: =U8-T8 -> 0 | Y8: =IFERROR(U8/T8,"0") -> 0
G9: 5 | H9: =IF(H8<$D$10,H8+1,"") -> 45693 | I9: =TEXT(H9,"DDD") -> Wed | J9: =IFERROR(VLOOKUP(H9,Sheet1!$A:$B,2,0),"") | M9: =IFERROR(IF(K9=0,"",K9/L9),"") | P9: =IFERROR(IF(N9=0,"",N9/O9),"") | S9: =IFERROR(IF(Q9=0,"",Q9/R9),"") | U9: =K9+N9+Q9 -> 0 | V9: =L9+O9+R9 -> 0 | W9: =IFERROR(U9/V9,"0") -> 0 | X9: =U9-T9 -> 0 | Y9: =IFERROR(U9/T9,"0") -> 0
C10: End Date | D10: =EOMONTH(D8,0) -> 45716 | G10: 6 | H10: =IF(H9<$D$10,H9+1,"") -> 45694 | I10: =TEXT(H10,"DDD") -> Thu | J10: =IFERROR(VLOOKUP(H10,Sheet1!$A:$B,2,0),"") | M10: =IFERROR(IF(K10=0,"",K10/L10),"") | P10: =IFERROR(IF(N10=0,"",N10/O10),"") | S10: =IFERROR(IF(Q10=0,"",Q10/R10),"") | U10: =K10+N10+Q10 -> 0 | V10: =L10+O10+R10 -> 0 | W10: =IFERROR(U10/V10,"0") -> 0 | X10: =U10-T10 -> 0 | Y10: =IFERROR(U10/T10,"0") -> 0
G11: 7 | H11: =IF(H10<$D$10,H10+1,"") -> 45695 | I11: =TEXT(H11,"DDD") -> Fri | J11: =IFERROR(VLOOKUP(H11,Sheet1!$A:$B,2,0),"") | M11: =IFERROR(IF(K11=0,"",K11/L11),"") | P11: =IFERROR(IF(N11=0,"",N11/O11),"") | S11: =IFERROR(IF(Q11=0,"",Q11/R11),"") | U11: =K11+N11+Q11 -> 0 | V11: =L11+O11+R11 -> 0 | W11: =IFERROR(U11/V11,"0") -> 0 | X11: =U11-T11 -> 0 | Y11: =IFERROR(U11/T11,"0") -> 0
C12: Total Days | D12: =COUNT(H5:H35) -> 28 | G12: 8 | H12: =IF(H11<$D$10,H11+1,"") -> 45696 | I12: =TEXT(H12,"DDD") -> Sat | J12: =IFERROR(VLOOKUP(H12,Sheet1!$A:$B,2,0),"") | M12: =IFERROR(IF(K12=0,"",K12/L12),"") | P12: =IFERROR(IF(N12=0,"",N12/O12),"") | S12: =IFERROR(IF(Q12=0,"",Q12/R12),"") | U12: =K12+N12+Q12 -> 0 | V12: =L12+O12+R12 -> 0 | W12: =IFERROR(U12/V12,"0") -> 0 | X12: =U12-T12 -> 0 | Y12: =IFERROR(U12/T12,"0") -> 0
G13: 9 | H13: =IF(H12<$D$10,H12+1,"") -> 45697 | I13: =TEXT(H13,"DDD") -> Sun | J13: =IFERROR(VLOOKUP(H13,Sheet1!$A:$B,2,0),"") | M13: =IFERROR(IF(K13=0,"",K13/L13),"") | P13: =IFERROR(IF(N13=0,"",N13/O13),"") | S13: =IFERROR(IF(Q13=0,"",Q13/R13),"") | U13: =K13+N13+Q13 -> 0 | V13: =L13+O13+R13 -> 0 | W13: =IFERROR(U13/V13,"0") -> 0 | X13: =U13-T13 -> 0 | Y13: =IFERROR(U13/T13,"0") -> 0
C14: Total Sat | D14: =COUNTIF(I5:I35,"Sat") -> 4 | G14: 10 | H14: =IF(H13<$D$10,H13+1,"") -> 45698 | I14: =TEXT(H14,"DDD") -> Mon | J14: =IFERROR(VLOOKUP(H14,Sheet1!$A:$B,2,0),"") | M14: =IFERROR(IF(K14=0,"",K14/L14),"") | P14: =IFERROR(IF(N14=0,"",N14/O14),"") | S14: =IFERROR(IF(Q14=0,"",Q14/R14),"") | U14: =K14+N14+Q14 -> 0 | V14: =L14+O14+R14 -> 0 | W14: =IFERROR(U14/V14,"0") -> 0 | X14: =U14-T14 -> 0 | Y14: =IFERROR(U14/T14,"0") -> 0
C15: Total Sun | D15: =COUNTIF(I5:I35,"Sun") -> 4 | G15: 11 | H15: =IF(H14<$D$10,H14+1,"") -> 45699 | I15: =TEXT(H15,"DDD") -> Tue | J15: =IFERROR(VLOOKUP(H15,Sheet1!$A:$B,2,0),"") | M15: =IFERROR(IF(K15=0,"",K15/L15),"") | P15: =IFERROR(IF(N15=0,"",N15/O15),"") | S15: =IFERROR(IF(Q15=0,"",Q15/R15),"") | U15: =K15+N15+Q15 -> 0 | V15: =L15+O15+R15 -> 0 | W15: =IFERROR(U15/V15,"0") -> 0 | X15: =U15-T15 -> 0 | Y15: =IFERROR(U15/T15,"0") -> 0
G16: 12 | H16: =IF(H15<$D$10,H15+1,"") -> 45700 | I16: =TEXT(H16,"DDD") -> Wed | J16: =IFERROR(VLOOKUP(H16,Sheet1!$A:$B,2,0),"") | M16: =IFERROR(IF(K16=0,"",K16/L16),"") | P16: =IFERROR(IF(N16=0,"",N16/O16),"") | S16: =IFERROR(IF(Q16=0,"",Q16/R16),"") | U16: =K16+N16+Q16 -> 0 | V16: =L16+O16+R16 -> 0 | W16: =IFERROR(U16/V16,"0") -> 0 | X16: =U16-T16 -> 0 | Y16: =IFERROR(U16/T16,"0") -> 0
C17: Highest Sale for the month | D17: =MAX(U5:U35) -> 0 | G17: 13 | H17: =IF(H16<$D$10,H16+1,"") -> 45701 | I17: =TEXT(H17,"DDD") -> Thu | J17: =IFERROR(VLOOKUP(H17,Sheet1!$A:$B,2,0),"") | M17: =IFERROR(IF(K17=0,"",K17/L17),"") | P17: =IFERROR(IF(N17=0,"",N17/O17),"") | S17: =IFERROR(IF(Q17=0,"",Q17/R17),"") | U17: =K17+N17+Q17 -> 0 | V17: =L17+O17+R17 -> 0 | W17: =IFERROR(U17/V17,"0") -> 0 | X17: =U17-T17 -> 0 | Y17: =IFERROR(U17/T17,"0") -> 0
G18: 14 | H18: =IF(H17<$D$10,H17+1,"") -> 45702 | I18: =TEXT(H18,"DDD") -> Fri | J18: =IFERROR(VLOOKUP(H18,Sheet1!$A:$B,2,0),"") | M18: =IFERROR(IF(K18=0,"",K18/L18),"") | P18: =IFERROR(IF(N18=0,"",N18/O18),"") | S18: =IFERROR(IF(Q18=0,"",Q18/R18),"") | U18: =K18+N18+Q18 -> 0 | V18: =L18+O18+R18 -> 0 | W18: =IFERROR(U18/V18,"0") -> 0 | X18: =U18-T18 -> 0 | Y18: =IFERROR(U18/T18,"0") -> 0
G19: 15 | H19: =IF(H18<$D$10,H18+1,"") -> 45703 | I19: =TEXT(H19,"DDD") -> Sat | J19: =IFERROR(VLOOKUP(H19,Sheet1!$A:$B,2,0),"") | M19: =IFERROR(IF(K19=0,"",K19/L19),"") | P19: =IFERROR(IF(N19=0,"",N19/O19),"") | S19: =IFERROR(IF(Q19=0,"",Q19/R19),"") | U19: =K19+N19+Q19 -> 0 | V19: =L19+O19+R19 -> 0 | W19: =IFERROR(U19/V19,"0") -> 0 | X19: =U19-T19 -> 0 | Y19: =IFERROR(U19/T19,"0") -> 0
C20: Lowest Sale for the month | D20: =MIN(U8:U38) -> 0 | G20: 16 | H20: =IF(H19<$D$10,H19+1,"") -> 45704 | I20: =TEXT(H20,"DDD") -> Sun | J20: =IFERROR(VLOOKUP(H20,Sheet1!$A:$B,2,0),"") | M20: =IFERROR(IF(K20=0,"",K20/L20),"") | P20: =IFERROR(IF(N20=0,"",N20/O20),"") | S20: =IFERROR(IF(Q20=0,"",Q20/R20),"") | U20: =K20+N20+Q20 -> 0 | V20: =L20+O20+R20 -> 0 | W20: =IFERROR(U20/V20,"0") -> 0 | X20: =U20-T20 -> 0 | Y20: =IFERROR(U20/T20,"0") -> 0
G21: 17 | H21: =IF(H20<$D$10,H20+1,"") -> 45705 | I21: =TEXT(H21,"DDD") -> Mon | J21: =IFERROR(VLOOKUP(H21,Sheet1!$A:$B,2,0),"") | M21: =IFERROR(IF(K21=0,"",K21/L21),"") | P21: =IFERROR(IF(N21=0,"",N21/O21),"") | S21: =IFERROR(IF(Q21=0,"",Q21/R21),"") | U21: =K21+N21+Q21 -> 0 | V21: =L21+O21+R21 -> 0 | W21: =IFERROR(U21/V21,"0") -> 0 | X21: =U21-T21 -> 0 | Y21: =IFERROR(U21/T21,"0") -> 0
G22: 18 | H22: =IF(H21<$D$10,H21+1,"") -> 45706 | I22: =TEXT(H22,"DDD") -> Tue | J22: =IFERROR(VLOOKUP(H22,Sheet1!$A:$B,2,0),"") | M22: =IFERROR(IF(K22=0,"",K22/L22),"") | P22: =IFERROR(IF(N22=0,"",N22/O22),"") | S22: =IFERROR(IF(Q22=0,"",Q22/R22),"") | U22: =K22+N22+Q22 -> 0 | V22: =L22+O22+R22 -> 0 | W22: =IFERROR(U22/V22,"0") -> 0 | X22: =U22-T22 -> 0 | Y22: =IFERROR(U22/T22,"0") -> 0
C23: Target Achieved | D23: =IF(U36>T36,"Yes","No") -> No | G23: 19 | H23: =IF(H22<$D$10,H22+1,"") -> 45707 | I23: =TEXT(H23,"DDD") -> Wed | J23: =IFERROR(VLOOKUP(H23,Sheet1!$A:$B,2,0),"") | M23: =IFERROR(IF(K23=0,"",K23/L23),"") | P23: =IFERROR(IF(N23=0,"",N23/O23),"") | S23: =IFERROR(IF(Q23=0,"",Q23/R23),"") | U23: =K23+N23+Q23 -> 0 | V23: =L23+O23+R23 -> 0 | W23: =IFERROR(U23/V23,"0") -> 0 | X23: =U23-T23 -> 0 | Y23: =IFERROR(U23/T23,"0") -> 0
G24: 20 | H24: =IF(H23<$D$10,H23+1,"") -> 45708 | I24: =TEXT(H24,"DDD") -> Thu | J24: =IFERROR(VLOOKUP(H24,Sheet1!$A:$B,2,0),"") | M24: =IFERROR(IF(K24=0,"",K24/L24),"") | P24: =IFERROR(IF(N24=0,"",N24/O24),"") | S24: =IFERROR(IF(Q24=0,"",Q24/R24),"") | U24: =K24+N24+Q24 -> 0 | V24: =L24+O24+R24 -> 0 | W24: =IFERROR(U24/V24,"0") -> 0 | X24: =U24-T24 -> 0 | Y24: =IFERROR(U24/T24,"0") -> 0
C25: Sales Till Date | D25: =U36 -> 0 | G25: 21 | H25: =IF(H24<$D$10,H24+1,"") -> 45709 | I25: =TEXT(H25,"DDD") -> Fri | J25: =IFERROR(VLOOKUP(H25,Sheet1!$A:$B,2,0),"") | M25: =IFERROR(IF(K25=0,"",K25/L25),"") | P25: =IFERROR(IF(N25=0,"",N25/O25),"") | S25: =IFERROR(IF(Q25=0,"",Q25/R25),"") | U25: =K25+N25+Q25 -> 0 | V25: =L25+O25+R25 -> 0 | W25: =IFERROR(U25/V25,"0") -> 0 | X25: =U25-T25 -> 0 | Y25: =IFERROR(U25/T25,"0") -> 0
G26: 22 | H26: =IF(H25<$D$10,H25+1,"") -> 45710 | I26: =TEXT(H26,"DDD") -> Sat | J26: =IFERROR(VLOOKUP(H26,Sheet1!$A:$B,2,0),"") | M26: =IFERROR(IF(K26=0,"",K26/L26),"") | P26: =IFERROR(IF(N26=0,"",N26/O26),"") | S26: =IFERROR(IF(Q26=0,"",Q26/R26),"") | U26: =K26+N26+Q26 -> 0 | V26: =L26+O26+R26 -> 0 | W26: =IFERROR(U26/V26,"0") -> 0 | X26: =U26-T26 -> 0 | Y26: =IFERROR(U26/T26,"0") -> 0
C27: Average Sales | D27: =IFERROR(AVERAGE(U5:U35),"0") -> 0 | G27: 23 | H27: =IF(H26<$D$10,H26+1,"") -> 45711 | I27: =TEXT(H27,"DDD") -> Sun | J27: =IFERROR(VLOOKUP(H27,Sheet1!$A:$B,2,0),"") | M27: =IFERROR(IF(K27=0,"",K27/L27),"") | P27: =IFERROR(IF(N27=0,"",N27/O27),"") | S27: =IFERROR(IF(Q27=0,"",Q27/R27),"") | U27: =K27+N27+Q27 -> 0 | V27: =L27+O27+R27 -> 0 | W27: =IFERROR(U27/V27,"0") -> 0 | X27: =U27-T27 -> 0 | Y27: =IFERROR(U27/T27,"0") -> 0
C28: Dine in Sales | D28: =K36 -> 0 | G28: 24 | H28: =IF(H27<$D$10,H27+1,"") -> 45712 | I28: =TEXT(H28,"DDD") -> Mon | J28: =IFERROR(VLOOKUP(H28,Sheet1!$A:$B,2,0),"") | M28: =IFERROR(IF(K28=0,"",K28/L28),"") | P28: =IFERROR(IF(N28=0,"",N28/O28),"") | S28: =IFERROR(IF(Q28=0,"",Q28/R28),"") | U28: =K28+N28+Q28 -> 0 | V28: =L28+O28+R28 -> 0 | W28: =IFERROR(U28/V28,"0") -> 0 | X28: =U28-T28 -> 0 | Y28: =IFERROR(U28/T28,"0") -> 0
C29: Takeaway Sales | D29: =N36 -> 0 | G29: 25 | H29: =IF(H28<$D$10,H28+1,"") -> 45713 | I29: =TEXT(H29,"DDD") -> Tue | J29: =IFERROR(VLOOKUP(H29,Sheet1!$A:$B,2,0),"") | M29: =IFERROR(IF(K29=0,"",K29/L29),"") | P29: =IFERROR(IF(N29=0,"",N29/O29),"") | S29: =IFERROR(IF(Q29=0,"",Q29/R29),"") | U29: =K29+N29+Q29 -> 0 | V29: =L29+O29+R29 -> 0 | W29: =IFERROR(U29/V29,"0") -> 0 | X29: =U29-T29 -> 0 | Y29: =IFERROR(U29/T29,"0") -> 0
C30: Delivery Sales | D30: =Q36 -> 0 | G30: 26 | H30: =IF(H29<$D$10,H29+1,"") -> 45714 | I30: =TEXT(H30,"DDD") -> Wed | J30: =IFERROR(VLOOKUP(H30,Sheet1!$A:$B,2,0),"") | M30: =IFERROR(IF(K30=0,"",K30/L30),"") | P30: =IFERROR(IF(N30=0,"",N30/O30),"") | S30: =IFERROR(IF(Q30=0,"",Q30/R30),"") | U30: =K30+N30+Q30 -> 0 | V30: =L30+O30+R30 -> 0 | W30: =IFERROR(U30/V30,"0") -> 0 | X30: =U30-T30 -> 0 | Y30: =IFERROR(U30/T30,"0") -> 0
G31: 27 | H31: =IF(H30<$D$10,H30+1,"") -> 45715 | I31: =TEXT(H31,"DDD") -> Thu | J31: =IFERROR(VLOOKUP(H31,Sheet1!$A:$B,2,0),"") | M31: =IFERROR(IF(K31=0,"",K31/L31),"") | P31: =IFERROR(IF(N31=0,"",N31/O31),"") | S31: =IFERROR(IF(Q31=0,"",Q31/R31),"") | U31: =K31+N31+Q31 -> 0 | V31: =L31+O31+R31 -> 0 | W31: =IFERROR(U31/V31,"0") -> 0 | X31: =U31-T31 -> 0 | Y31: =IFERROR(U31/T31,"0") -> 0
C32: Total Sales | D32: =SUM(D28:D30) -> 0 | G32: 28 | H32: =IF(H31<$D$10,H31+1,"") -> 45716 | I32: =TEXT(H32,"DDD") -> Fri | J32: =IFERROR(VLOOKUP(H32,Sheet1!$A:$B,2,0),"") | M32: =IFERROR(IF(K32=0,"",K32/L32),"") | P32: =IFERROR(IF(N32=0,"",N32/O32),"") | S32: =IFERROR(IF(Q32=0,"",Q32/R32),"") | U32: =K32+N32+Q32 -> 0 | V32: =L32+O32+R32 -> 0 | W32: =IFERROR(U32/V32,"0") -> 0 | X32: =U32-T32 -> 0 | Y32: =IFERROR(U32/T32,"0") -> 0
C33: Last year sales | D33: 5000 | G33: 29 | H33: =IF(H32<$D$10,H32+1,"") | I33: =TEXT(H33,"DDD") | J33: =IFERROR(VLOOKUP(H33,Sheet1!$A:$B,2,0),"") | M33: =IFERROR(IF(K33=0,"",K33/L33),"") | P33: =IFERROR(IF(N33=0,"",N33/O33),"") | S33: =IFERROR(IF(Q33=0,"",Q33/R33),"") | U33: =K33+N33+Q33 -> 0 | V33: =L33+O33+R33 -> 0 | W33: =IFERROR(U33/V33,"0") -> 0 | X33: =U33-T33 -> 0 | Y33: =IFERROR(U33/T33,"0") -> 0
C34: Growth | D34: =D32-D33 -> -5000 | G34: 30 | H34: =IF(H33<$D$10,H33+1,"") | I34: =TEXT(H34,"DDD") | J34: =IFERROR(VLOOKUP(H34,Sheet1!$A:$B,2,0),"") | M34: =IFERROR(IF(K34=0,"",K34/L34),"") | P34: =IFERROR(IF(N34=0,"",N34/O34),"") | S34: =IFERROR(IF(Q34=0,"",Q34/R34),"") | U34: =K34+N34+Q34 -> 0 | V34: =L34+O34+R34 -> 0 | W34: =IFERROR(U34/V34,"0") -> 0 | X34: =U34-T34 -> 0 | Y34: =IFERROR(U34/T34,"0") -> 0
C35: Growth % | D35: =IFERROR((D32-D33)/D33,"0") -> -1 | G35: 31 | H35: =IF(H34<$D$10,H34+1,"") | I35: =TEXT(H35,"DDD") | J35: =IFERROR(VLOOKUP(H35,Sheet1!$A:$B,2,0),"") | M35: =IFERROR(IF(K35=0,"",K35/L35),"") | P35: =IFERROR(IF(N35=0,"",N35/O35),"") | S35: =IFERROR(IF(Q35=0,"",Q35/R35),"") | U35: =K35+N35+Q35 -> 0 | V35: =L35+O35+R35 -> 0 | W35: =IFERROR(U35/V35,"0") -> 0 | X35: =U35-T35 -> 0 | Y35: =IFERROR(U35/T35,"0") -> 0
G36: Total | K36: =SUM(K5:K35) -> 0 | L36: =SUM(L5:L35) -> 0 | M36: =IFERROR(K36/L36,"0") -> 0 | N36: =SUM(N5:N35) -> 0 | O36: =SUM(O5:O35) -> 0 | P36: =IFERROR(N36/O36,"0") -> 0 | Q36: =SUM(Q5:Q35) -> 0 | R36: =SUM(R5:R35) -> 0 | S36: =IFERROR(Q36/R36,"0") -> 0 | T36: =SUM(T5:T35) -> 0 | U36: =SUM(U5:U35) -> 0 | V36: =SUM(V5:V35) -> 0 | W36: =IFERROR(U36/V36,"0") -> 0 | X36: =SUM(X5:X35) -> 0 | Y36: =SUM(Y5:Y35) -> 0

Sheet Mar
B2: Summary
G3: Daily Sales Report | T3: Consolidated
C4: Month | D4: Mar | G4: Sr No. | H4: Date | I4: Day | J4: Holidays | K4: Dine in Sales | L4: Dine in Tkts. | M4: APC/APT(Avg. /Transaction) | N4: TA Sales | O4: TA Tkts. | P4: APC/APT(Avg. /Transaction) | Q4: Delivery Sales | R4: Delivery Tkts. | S4: APC/APT(Avg. /Transaction) | T4: Target Sales | U4: Total Sales | V4: Total Tkts. | W4: APC/APT | X4: Target vs Acheived | Y4: %
G5: 1 | H5: =D8 -> 45717 | I5: =TEXT(H5,"DDD") -> Sat | J5: =IFERROR(VLOOKUP(H5,Sheet1!$A:$B,2,0),"") | M5: =IFERROR(IF(K5=0,"",K5/L5),"") | P5: =IFERROR(IF(N5=0,"",N5/O5),"") | S5: =IFERROR(IF(Q5=0,"",Q5/R5),"") | U5: =K5+N5+Q5 -> 0 | V5: =L5+O5+R5 -> 0 | W5: =IFERROR(U5/V5,"0") -> 0 | X5: =U5-T5 -> 0 | Y5: =IFERROR(U5/T5,"0") -> 0
C6: Year | D6: 2025 | G6: 2 | H6: =IF(H5<$D$10,H5+1,"") -> 45718 | I6: =TEXT(H6,"DDD") -> Sun | J6: =IFERROR(VLOOKUP(H6,Sheet1!$A:$B,2,0),"") | M6: =IFERROR(IF(K6=0,"",K6/L6),"") | P6: =IFERROR(IF(N6=0,"",N6/O6),"") | S6: =IFERROR(IF(Q6=0,"",Q6/R6),"") | U6: =K6+N6+Q6 -> 0 | V6: =L6+O6+R6 -> 0 | W6: =IFERROR(U6/V6,"0") -> 0 | X6: =U6-T6 -> 0 | Y6: =IFERROR(U6/T6,"0") -> 0
G7: 3 | H7: =IF(H6<$D$10,H6+1,"") -> 45719 | I7: =TEXT(H7,"DDD") -> Mon | J7: =IFERROR(VLOOKUP(H7,Sheet1!$A:$B,2,0),"") | M7: =IFERROR(IF(K7=0,"",K7/L7),"") | P7: =IFERROR(IF(N7=0,"",N7/O7),"") | S7: =IFERROR(IF(Q7=0,"",Q7/R7),"") | U7: =K7+N7+Q7 -> 0 | V7: =L7+O7+R7 -> 0 | W7: =IFERROR(U7/V7,"0") -> 0 | X7: =U7-T7 -> 0 | Y7: =IFERROR(U7/T7,"0") -> 0
C8: Start Date | D8: =DATEVALUE("01"&D4&D6) -> 45717 | G8: 4 | H8: =IF(H7<$D$10,H7+1,"") -> 45720 | I8: =TEXT(H8,"DDD") -> Tue | J8: =IFERROR(VLOOKUP(H8,Sheet1!$A:$B,2,0),"") | M8: =IFERROR(IF(K8=0,"",K8/L8),"") | P8: =IFERROR(IF(N8=0,"",N8/O8),"") | S8: =IFERROR(IF(Q8=0,"",Q8/R8),"") | U8: =K8+N8+Q8 -> 0 | V8: =L8+O8+R8 -> 0 | W8: =IFERROR(U8/V8,"0") -> 0 | X8: =U8-T8 -> 0 | Y8: =IFERROR(U8/T8,"0") -> 0
G9: 5 | H9: =IF(H8<$D$10,H8+1,"") -> 45721 | I9: =TEXT(H9,"DDD") -> Wed | J9: =IFERROR(VLOOKUP(H9,Sheet1!$A:$B,2,0),"") | M9: =IFERROR(IF(K9=0,"",K9/L9),"") | P9: =IFERROR(IF(N9=0,"",N9/O9),"") | S9: =IFERROR(IF(Q9=0,"",Q9/R9),"") | U9: =K9+N9+Q9 -> 0 | V9: =L9+O9+R9 -> 0 | W9: =IFERROR(U9/V9,"0") -> 0 | X9: =U9-T9 -> 0 | Y9: =IFERROR(U9/T9,"0") -> 0
C10: End Date | D10: =EOMONTH(D8,0) -> 45747 | G10: 6 | H10: =IF(H9<$D$10,H9+1,"") -> 45722 | I10: =TEXT(H10,"DDD") -> Thu | J10: =IFERROR(VLOOKUP(H10,Sheet1!$A:$B,2,0),"") | M10: =IFERROR(IF(K10=0,"",K10/L10),"") | P10: =IFERROR(IF(N10=0,"",N10/O10),"") | S10: =IFERROR(IF(Q10=0,"",Q10/R10),"") | U10: =K10+N10+Q10 -> 0 | V10: =L10+O10+R10 -> 0 | W10: =IFERROR(U10/V10,"0") -> 0 | X10: =U10-T10 -> 0 | Y10: =IFERROR(U10/T10,"0") -> 0
G11: 7 | H11: =IF(H10<$D$10,H10+1,"") -> 45723 | I11: =TEXT(H11,"DDD") -> Fri | J11: =IFERROR(VLOOKUP(H11,Sheet1!$A:$B,2,0),"") | M11: =IFERROR(IF(K11=0,"",K11/L11),"") | P11: =IFERROR(IF(N11=0,"",N11/O11),"") | S11: =IFERROR(IF(Q11=0,"",Q11/R11),"") | U11: =K11+N11+Q11 -> 0 | V11: =L11+O11+R11 -> 0 | W11: =IFERROR(U11/V11,"0") -> 0 | X11: =U11-T11 -> 0 | Y11: =IFERROR(U11/T11,"0") -> 0
C12: Total Days | D12: =COUNT(H5:H35) -> 31 | G12: 8 | H12: =IF(H11<$D$10,H11+1,"") -> 45724 | I12: =TEXT(H12,"DDD") -> Sat | J12: =IFERROR(VLOOKUP(H12,Sheet1!$A:$B,2,0),"") -> Holi | M12: =IFERROR(IF(K12=0,"",K12/L12),"") | P12: =IFERROR(IF(N12=0,"",N12/O12),"") | S12: =IFERROR(IF(Q12=0,"",Q12/R12),"") | U12: =K12+N12+Q12 -> 0 | V12: =L12+O12+R12 -> 0 | W12: =IFERROR(U12/V12,"0") -> 0 | X12: =U12-T12 -> 0 | Y12: =IFERROR(U12/T12,"0") -> 0
G13: 9 | H13: =IF(H12<$D$10,H12+1,"") -> 45725 | I13: =TEXT(H13,"DDD") -> Sun | J13: =IFERROR(VLOOKUP(H13,Sheet1!$A:$B,2,0),"") | M13: =IFERROR(IF(K13=0,"",K13/L13),"") | P13: =IFERROR(IF(N13=0,"",N13/O13),"") | S13: =IFERROR(IF(Q13=0,"",Q13/R13),"") | U13: =K13+N13+Q13 -> 0 | V13: =L13+O13+R13 -> 0 | W13: =IFERROR(U13/V13,"0") -> 0 | X13: =U13-T13 -> 0 | Y13: =IFERROR(U13/T13,"0") -> 0
C14: Total Sat | D14: =COUNTIF(I5:I35,"Sat") -> 5 | G14: 10 | H14: =IF(H13<$D$10,H13+1,"") -> 45726 | I14: =TEXT(H14,"DDD") -> Mon | J14: =IFERROR(VLOOKUP(H14,Sheet1!$A:$B,2,0),"") | M14: =IFERROR(IF(K14=0,"",K14/L14),"") | P14: =IFERROR(IF(N14=0,"",N14/O14),"") | S14: =IFERROR(IF(Q14=0,"",Q14/R14),"") | U14: =K14+N14+Q14 -> 0 | V14: =L14+O14+R14 -> 0 | W14: =IFERROR(U14/V14,"0") -> 0 | X14: =U14-T14 -> 0 | Y14: =IFERROR(U14/T14,"0") -> 0
C15: Total Sun | D15: =COUNTIF(I5:I35,"Sun") -> 5 | G15: 11 | H15: =IF(H14<$D$10,H14+1,"") -> 45727 | I15: =TEXT(H15,"DDD") -> Tue | J15: =IFERROR(VLOOKUP(H15,Sheet1!$A:$B,2,0),"") | M15: =IFERROR(IF(K15=0,"",K15/L15),"") | P15: =IFERROR(IF(N15=0,"",N15/O15),"") | S15: =IFERROR(IF(Q15=0,"",Q15/R15),"") | U15: =K15+N15+Q15 -> 0 | V15: =L15+O15+R15 -> 0 | W15: =IFERROR(U15/V15,"0") -> 0 | X15: =U15-T15 -> 0 | Y15: =IFERROR(U15/T15,"0") -> 0
G16: 12 | H16: =IF(H15<$D$10,H15+1,"") -> 45728 | I16: =TEXT(H16,"DDD") -> Wed | J16: =IFERROR(VLOOKUP(H16,Sheet1!$A:$B,2,0),"") | M16: =IFERROR(IF(K16=0,"",K16/L16),"") | P16: =IFERROR(IF(N16=0,"",N16/O16),"") | S16: =IFERROR(IF(Q16=0,"",Q16/R16),"") | U16: =K16+N16+Q16 -> 0 | V16: =L16+O16+R16 -> 0 | W16: =IFERROR(U16/V16,"0") -> 0 | X16: =U16-T16 -> 0 | Y16: =IFERROR(U16/T16,"0") -> 0
C17: Highest Sale for the month | D17: =MAX(U5:U35) -> 0 | G17: 13 | H17: =IF(H16<$D$10,H16+1,"") -> 45729 | I17: =TEXT(H17,"DDD") -> Thu | J17: =IFERROR(VLOOKUP(H17,Sheet1!$A:$B,2,0),"") | M17: =IFERROR(IF(K17=0,"",K17/L17),"") | P17: =IFERROR(IF(N17=0,"",N17/O17),"") | S17: =IFERROR(IF(Q17=0,"",Q17/R17),"") | U17: =K17+N17+Q17 -> 0 | V17: =L17+O17+R17 -> 0 | W17: =IFERROR(U17/V17,"0") -> 0 | X17: =U17-T17 -> 0 | Y17: =IFERROR(U17/T17,"0") -> 0
G18: 14 | H18: =IF(H17<$D$10,H17+1,"") -> 45730 | I18: =TEXT(H18,"DDD") -> Fri | J18: =IFERROR(VLOOKUP(H18,Sheet1!$A:$B,2,0),"") | M18: =IFERROR(IF(K18=0,"",K18/L18),"") | P18: =IFERROR(IF(N18=0,"",N18/O18),"") | S18: =IFERROR(IF(Q18=0,"",Q18/R18),"") | U18: =K18+N18+Q18 -> 0 | V18: =L18+O18+R18 -> 0 | W18: =IFERROR(U18/V18,"0") -> 0 | X18: =U18-T18 -> 0 | Y18: =IFERROR(U18/T18,"0") -> 0
G19: 15 | H19: =IF(H18<$D$10,H18+1,"") -> 45731 | I19: =TEXT(H19,"DDD") -> Sat | J19: =IFERROR(VLOOKUP(H19,Sheet1!$A:$B,2,0),"") | M19: =IFERROR(IF(K19=0,"",K19/L19),"") | P19: =IFERROR(IF(N19=0,"",N19/O19),"") | S19: =IFERROR(IF(Q19=0,"",Q19/R19),"") | U19: =K19+N19+Q19 -> 0 | V19: =L19+O19+R19 -> 0 | W19: =IFERROR(U19/V19,"0") -> 0 | X19: =U19-T19 -> 0 | Y19: =IFERROR(U19/T19,"0") -> 0
C20: Lowest Sale for the month | D20: =MIN(U8:U38) -> 0 | G20: 16 | H20: =IF(H19<$D$10,H19+1,"") -> 45732 | I20: =TEXT(H20,"DDD") -> Sun | J20: =IFERROR(VLOOKUP(H20,Sheet1!$A:$B,2,0),"") | M20: =IFERROR(IF(K20=0,"",K20/L20),"") | P20: =IFERROR(IF(N20=0,"",N20/O20),"") | S20: =IFERROR(IF(Q20=0,"",Q20/R20),"") | U20: =K20+N20+Q20 -> 0 | V20: =L20+O20+R20 -> 0 | W20: =IFERROR(U20/V20,"0") -> 0 | X20: =U20-T20 -> 0 | Y20: =IFERROR(U20/T20,"0") -> 0
G21: 17 | H21: =IF(H20<$D$10,H20+1,"") -> 45733 | I21: =TEXT(H21,"DDD") -> Mon | J21: =IFERROR(VLOOKUP(H21,Sheet1!$A:$B,2,0),"") | M21: =IFERROR(IF(K21=0,"",K21/L21),"") | P21: =IFERROR(IF(N21=0,"",N21/O21),"") | S21: =IFERROR(IF(Q21=0,"",Q21/R21),"") | U21: =K21+N21+Q21 -> 0 | V21: =L21+O21+R21 -> 0 | W21: =IFERROR(U21/V21,"0") -> 0 | X21: =U21-T21 -> 0 | Y21: =IFERROR(U21/T21,"0") -> 0
G22: 18 | H22: =IF(H21<$D$10,H21+1,"") -> 45734 | I22: =TEXT(H22,"DDD") -> Tue | J22: =IFERROR(VLOOKUP(H22,Sheet1!$A:$B,2,0),"") | M22: =IFERROR(IF(K22=0,"",K22/L22),"") | P22: =IFERROR(IF(N22=0,"",N22/O22),"") | S22: =IFERROR(IF(Q22=0,"",Q22/R22),"") | U22: =K22+N22+Q22 -> 0 | V22: =L22+O22+R22 -> 0 | W22: =IFERROR(U22/V22,"0") -> 0 | X22: =U22-T22 -> 0 | Y22: =IFERROR(U22/T22,"0") -> 0
C23: Target Achieved | D23: =IF(U36>T36,"Yes","No") -> No | G23: 19 | H23: =IF(H22<$D$10,H22+1,"") -> 45735 | I23: =TEXT(H23,"DDD") -> Wed | J23: =IFERROR(VLOOKUP(H23,Sheet1!$A:$B,2,0),"") | M23: =IFERROR(IF(K23=0,"",K23/L23),"") | P23: =IFERROR(IF(N23=0,"",N23/O23),"") | S23: =IFERROR(IF(Q23=0,"",Q23/R23),"") | U23: =K23+N23+Q23 -> 0 | V23: =L23+O23+R23 -> 0 | W23: =IFERROR(U23/V23,"0") -> 0 | X23: =U23-T23 -> 0 | Y23: =IFERROR(U23/T23,"0") -> 0
G24: 20 | H24: =IF(H23<$D$10,H23+1,"") -> 45736 | I24: =TEXT(H24,"DDD") -> Thu | J24: =IFERROR(VLOOKUP(H24,Sheet1!$A:$B,2,0),"") | M24: =IFERROR(IF(K24=0,"",K24/L24),"") | P24: =IFERROR(IF(N24=0,"",N24/O24),"") | S24: =IFERROR(IF(Q24=0,"",Q24/R24),"") | U24: =K24+N24+Q24 -> 0 | V24: =L24+O24+R24 -> 0 | W24: =IFERROR(U24/V24,"0") -> 0 | X24: =U24-T24 -> 0 | Y24: =IFERROR(U24/T24,"0") -> 0
C25: Sales Till Date | D25: =U36 -> 0 | G25: 21 | H25: =IF(H24<$D$10,H24+1,"") -> 45737 | I25: =TEXT(H25,"DDD") -> Fri | J25: =IFERROR(VLOOKUP(H25,Sheet1!$A:$B,2,0),"") | M25: =IFERROR(IF(K25=0,"",K25/L25),"") | P25: =IFERROR(IF(N25=0,"",N25/O25),"") | S25: =IFERROR(IF(Q25=0,"",Q25/R25),"") | U25: =K25+N25+Q25 -> 0 | V25: =L25+O25+R25 -> 0 | W25: =IFERROR(U25/V25,"0") -> 0 | X25: =U25-T25 -> 0 | Y25: =IFERROR(U25/T25,"0") -> 0
G26: 22 | H26: =IF(H25<$D$10,H25+1,"") -> 45738 | I26: =TEXT(H26,"DDD") -> Sat | J26: =IFERROR(VLOOKUP(H26,Sheet1!$A:$B,2,0),"") | M26: =IFERROR(IF(K26=0,"",K26/L26),"") | P26: =IFERROR(IF(N26=0,"",N26/O26),"") | S26: =IFERROR(IF(Q26=0,"",Q26/R26),"") | U26: =K26+N26+Q26 -> 0 | V26: =L26+O26+R26 -> 0 | W26: =IFERROR(U26/V26,"0") -> 0 | X26: =U26-T26 -> 0 | Y26: =IFERROR(U26/T26,"0") -> 0
C27: Average Sales | D27: =IFERROR(AVERAGE(U5:U35),"0") -> 0 | G27: 23 | H27: =IF(H26<$D$10,H26+1,"") -> 45739 | I27: =TEXT(H27,"DDD") -> Sun | J27: =IFERROR(VLOOKUP(H27,Sheet1!$A:$B,2,0),"") | M27: =IFERROR(IF(K27=0,"",K27/L27),"") | P27: =IFERROR(IF(N27=0,"",N27/O27),"") | S27: =IFERROR(IF(Q27=0,"",Q27/R27),"") | U27: =K27+N27+Q27 -> 0 | V27: =L27+O27+R27 -> 0 | W27: =IFERROR(U27/V27,"0") -> 0 | X27: =U27-T27 -> 0 | Y27: =IFERROR(U27/T27,"0") -> 0
C28: Dine in Sales | D28: =K36 -> 0 | G28: 24 | H28: =IF(H27<$D$10,H27+1,"") -> 45740 | I28: =TEXT(H28,"DDD") -> Mon | J28: =IFERROR(VLOOKUP(H28,Sheet1!$A:$B,2,0),"") | M28: =IFERROR(IF(K28=0,"",K28/L28),"") | P28: =IFERROR(IF(N28=0,"",N28/O28),"") | S28: =IFERROR(IF(Q28=0,"",Q28/R28),"") | U28: =K28+N28+Q28 -> 0 | V28: =L28+O28+R28 -> 0 | W28: =IFERROR(U28/V28,"0") -> 0 | X28: =U28-T28 -> 0 | Y28: =IFERROR(U28/T28,"0") -> 0
C29: Takeaway Sales | D29: =N36 -> 0 | G29: 25 | H29: =IF(H28<$D$10,H28+1,"") -> 45741 | I29: =TEXT(H29,"DDD") -> Tue | J29: =IFERROR(VLOOKUP(H29,Sheet1!$A:$B,2,0),"") | M29: =IFERROR(IF(K29=0,"",K29/L29),"") | P29: =IFERROR(IF(N29=0,"",N29/O29),"") | S29: =IFERROR(IF(Q29=0,"",Q29/R29),"") | U29: =K29+N29+Q29 -> 0 | V29: =L29+O29+R29 -> 0 | W29: =IFERROR(U29/V29,"0") -> 0 | X29: =U29-T29 -> 0 | Y29: =IFERROR(U29/T29,"0") -> 0
C30: Delivery Sales | D30: =Q36 -> 0 | G30: 26 | H30: =IF(H29<$D$10,H29+1,"") -> 45742 | I30: =TEXT(H30,"DDD") -> Wed | J30: =IFERROR(VLOOKUP(H30,Sheet1!$A:$B,2,0),"") | M30: =IFERROR(IF(K30=0,"",K30/L30),"") | P30: =IFERROR(IF(N30=0,"",N30/O30),"") | S30: =IFERROR(IF(Q30=0,"",Q30/R30),"") | U30: =K30+N30+Q30 -> 0 | V30: =L30+O30+R30 -> 0 | W30: =IFERROR(U30/V30,"0") -> 0 | X30: =U30-T30 -> 0 | Y30: =IFERROR(U30/T30,"0") -> 0
G31: 27 | H31: =IF(H30<$D$10,H30+1,"") -> 45743 | I31: =TEXT(H31,"DDD") -> Thu | J31: =IFERROR(VLOOKUP(H31,Sheet1!$A:$B,2,0),"") | M31: =IFERROR(IF(K31=0,"",K31/L31),"") | P31: =IFERROR(IF(N31=0,"",N31/O31),"") | S31: =IFERROR(IF(Q31=0,"",Q31/R31),"") | U31: =K31+N31+Q31 -> 0 | V31: =L31+O31+R31 -> 0 | W31: =IFERROR(U31/V31,"0") -> 0 | X31: =U31-T31 -> 0 | Y31: =IFERROR(U31/T31,"0") -> 0
C32: Total Sales | D32: =SUM(D28:D30) -> 0 | G32: 28 | H32: =IF(H31<$D$10,H31+1,"") -> 45744 | I32: =TEXT(H32,"DDD") -> Fri | J32: =IFERROR(VLOOKUP(H32,Sheet1!$A:$B,2,0),"") | M32: =IFERROR(IF(K32=0,"",K32/L32),"") | P32: =IFERROR(IF(N32=0,"",N32/O32),"") | S32: =IFERROR(IF(Q32=0,"",Q32/R32),"") | U32: =K32+N32+Q32 -> 0 | V32: =L32+O32+R32 -> 0 | W32: =IFERROR(U32/V32,"0") -> 0 | X32: =U32-T32 -> 0 | Y32: =IFERROR(U32/T32,"0") -> 0
C33: Last year sales | D33: 5000 | G33: 29 | H33: =IF(H32<$D$10,H32+1,"") -> 45745 | I33: =TEXT(H33,"DDD") -> Sat | J33: =IFERROR(VLOOKUP(H33,Sheet1!$A:$B,2,0),"") | M33: =IFERROR(IF(K33=0,"",K33/L33),"") | P33: =IFERROR(IF(N33=0,"",N33/O33),"") | S33: =IFERROR(IF(Q33=0,"",Q33/R33),"") | U33: =K33+N33+Q33 -> 0 | V33: =L33+O33+R33 -> 0 | W33: =IFERROR(U33/V33,"0") -> 0 | X33: =U33-T33 -> 0 | Y33: =IFERROR(U33/T33,"0") -> 0
C34: Growth | D34: =D32-D33 -> -5000 | G34: 30 | H34: =IF(H33<$D$10,H33+1,"") -> 45746 | I34: =TEXT(H34,"DDD") -> Sun | J34: =IFERROR(VLOOKUP(H34,Sheet1!$A:$B,2,0),"") | M34: =IFERROR(IF(K34=0,"",K34/L34),"") | P34: =IFERROR(IF(N34=0,"",N34/O34),"") | S34: =IFERROR(IF(Q34=0,"",Q34/R34),"") | U34: =K34+N34+Q34 -> 0 | V34: =L34+O34+R34 -> 0 | W34: =IFERROR(U34/V34,"0") -> 0 | X34: =U34-T34 -> 0 | Y34: =IFERROR(U34/T34,"0") -> 0
C35: Growth % | D35: =IFERROR((D32-D33)/D33,"0") -> -1 | G35: 31 | H35: =IF(H34<$D$10,H34+1,"") -> 45747 | I35: =TEXT(H35,"DDD") -> Mon | J35: =IFERROR(VLOOKUP(H35,Sheet1!$A:$B,2,0),"") | M35: =IFERROR(IF(K35=0,"",K35/L35),"") | P35: =IFERROR(IF(N35=0,"",N35/O35),"") | S35: =IFERROR(IF(Q35=0,"",Q35/R35),"") | U35: =K35+N35+Q35 -> 0 | V35: =L35+O35+R35 -> 0 | W35: =IFERROR(U35/V35,"0") -> 0 | X35: =U35-T35 -> 0 | Y35: =IFERROR(U35/T35,"0") -> 0
G36: Total | K36: =SUM(K5:K35) -> 0 | L36: =SUM(L5:L35) -> 0 | M36: =IFERROR(K36/L36,"0") -> 0 | N36: =SUM(N5:N35) -> 0 | O36: =SUM(O5:O35) -> 0 | P36: =IFERROR(N36/O36,"0") -> 0 | Q36: =SUM(Q5:Q35) -> 0 | R36: =SUM(R5:R35) -> 0 | S36: =IFERROR(Q36/R36,"0") -> 0 | T36: =SUM(T5:T35) -> 0 | U36: =SUM(U5:U35) -> 0 | V36: =SUM(V5:V35) -> 0 | W36: =IFERROR(U36/V36,"0") -> 0 | X36: =SUM(X5:X35) -> 0 | Y36: =SUM(Y5:Y35) -> 0

Sheet Apr
B2: Summary
G3: Daily Sales Report | T3: Consolidated
C4: Month | D4: Apr | G4: Sr No. | H4: Date | I4: Day | J4: Holidays | K4: Dine in Sales | L4: Dine in Tkts. | M4: APC/APT(Avg. /Transaction) | N4: TA Sales | O4: TA Tkts. | P4: APC/APT(Avg. /Transaction) | Q4: Delivery Sales | R4: Delivery Tkts. | S4: APC/APT(Avg. /Transaction) | T4: Target Sales | U4: Total Sales | V4: Total Tkts. | W4: APC/APT | X4: Target vs Acheived | Y4: %
G5: 1 | H5: =D8 -> 45748 | I5: =TEXT(H5,"DDD") -> Tue | J5: =IFERROR(VLOOKUP(H5,Sheet1!$A:$B,2,0),"") | M5: =IFERROR(IF(K5=0,"",K5/L5),"") | P5: =IFERROR(IF(N5=0,"",N5/O5),"") | S5: =IFERROR(IF(Q5=0,"",Q5/R5),"") | U5: =K5+N5+Q5 -> 0 | V5: =L5+O5+R5 -> 0 | W5: =IFERROR(U5/V5,"0") -> 0 | X5: =U5-T5 -> 0 | Y5: =IFERROR(U5/T5,"0") -> 0
C6: Year | D6: 2025 | G6: 2 | H6: =IF(H5<$D$10,H5+1,"") -> 45749 | I6: =TEXT(H6,"DDD") -> Wed | J6: =IFERROR(VLOOKUP(H6,Sheet1!$A:$B,2,0),"") | M6: =IFERROR(IF(K6=0,"",K6/L6),"") | P6: =IFERROR(IF(N6=0,"",N6/O6),"") | S6: =IFERROR(IF(Q6=0,"",Q6/R6),"") | U6: =K6+N6+Q6 -> 0 | V6: =L6+O6+R6 -> 0 | W6: =IFERROR(U6/V6,"0") -> 0 | X6: =U6-T6 -> 0 | Y6: =IFERROR(U6/T6,"0") -> 0
G7: 3 | H7: =IF(H6<$D$10,H6+1,"") -> 45750 | I7: =TEXT(H7,"DDD") -> Thu | J7: =IFERROR(VLOOKUP(H7,Sheet1!$A:$B,2,0),"") | M7: =IFERROR(IF(K7=0,"",K7/L7),"") | P7: =IFERROR(IF(N7=0,"",N7/O7),"") | S7: =IFERROR(IF(Q7=0,"",Q7/R7),"") | U7: =K7+N7+Q7 -> 0 | V7: =L7+O7+R7 -> 0 | W7: =IFERROR(U7/V7,"0") -> 0 | X7: =U7-T7 -> 0 | Y7: =IFERROR(U7/T7,"0") -> 0
C8: Start Date | D8: =DATEVALUE("01"&D4&D6) -> 45748 | G8: 4 | H8: =IF(H7<$D$10,H7+1,"") -> 45751 | I8: =TEXT(H8,"DDD") -> Fri | J8: =IFERROR(VLOOKUP(H8,Sheet1!$A:$B,2,0),"") | M8: =IFERROR(IF(K8=0,"",K8/L8),"") | P8: =IFERROR(IF(N8=0,"",N8/O8),"") | S8: =IFERROR(IF(Q8=0,"",Q8/R8),"") | U8: =K8+N8+Q8 -> 0 | V8: =L8+O8+R8 -> 0 | W8: =IFERROR(U8/V8,"0") -> 0 | X8: =U8-T8 -> 0 | Y8: =IFERROR(U8/T8,"0") -> 0
G9: 5 | H9: =IF(H8<$D$10,H8+1,"") -> 45752 | I9: =TEXT(H9,"DDD") -> Sat | J9: =IFERROR(VLOOKUP(H9,Sheet1!$A:$B,2,0),"") | M9: =IFERROR(IF(K9=0,"",K9/L9),"") | P9: =IFERROR(IF(N9=0,"",N9/O9),"") | S9: =IFERROR(IF(Q9=0,"",Q9/R9),"") | U9: =K9+N9+Q9 -> 0 | V9: =L9+O9+R9 -> 0 | W9: =IFERROR(U9/V9,"0") -> 0 | X9: =U9-T9 -> 0 | Y9: =IFERROR(U9/T9,"0") -> 0
C10: End Date | D10: =EOMONTH(D8,0) -> 45777 | G10: 6 | H10: =IF(H9<$D$10,H9+1,"") -> 45753 | I10: =TEXT(H10,"DDD") -> Sun | J10: =IFERROR(VLOOKUP(H10,Sheet1!$A:$B,2,0),"") | M10: =IFERROR(IF(K10=0,"",K10/L10),"") | P10: =IFERROR(IF(N10=0,"",N10/O10),"") | S10: =IFERROR(IF(Q10=0,"",Q10/R10),"") | U10: =K10+N10+Q10 -> 0 | V10: =L10+O10+R10 -> 0 | W10: =IFERROR(U10/V10,"0") -> 0 | X10: =U10-T10 -> 0 | Y10: =IFERROR(U10/T10,"0") -> 0
G11: 7 | H11: =IF(H10<$D$10,H10+1,"") -> 45754 | I11: =TEXT(H11,"DDD") -> Mon | J11: =IFERROR(VLOOKUP(H11,Sheet1!$A:$B,2,0),"") -> Good Friday | M11: =IFERROR(IF(K11=0,"",K11/L11),"") | P11: =IFERROR(IF(N11=0,"",N11/O11),"") | S11: =IFERROR(IF(Q11=0,"",Q11/R11),"") | U11: =K11+N11+Q11 -> 0 | V11: =L11+O11+R11 -> 0 | W11: =IFERROR(U11/V11,"0") -> 0 | X11: =U11-T11 -> 0 | Y11: =IFERROR(U11/T11,"0") -> 0
C12: Total Days | D12: =COUNT(H5:H35) -> 30 | G12: 8 | H12: =IF(H11<$D$10,H11+1,"") -> 45755 | I12: =TEXT(H12,"DDD") -> Tue | J12: =IFERROR(VLOOKUP(H12,Sheet1!$A:$B,2,0),"") | M12: =IFERROR(IF(K12=0,"",K12/L12),"") | P12: =IFERROR(IF(N12=0,"",N12/O12),"") | S12: =IFERROR(IF(Q12=0,"",Q12/R12),"") | U12: =K12+N12+Q12 -> 0 | V12: =L12+O12+R12 -> 0 | W12: =IFERROR(U12/V12,"0") -> 0 | X12: =U12-T12 -> 0 | Y12: =IFERROR(U12/T12,"0") -> 0
G13: 9 | H13: =IF(H12<$D$10,H12+1,"") -> 45756 | I13: =TEXT(H13,"DDD") -> Wed | J13: =IFERROR(VLOOKUP(H13,Sheet1!$A:$B,2,0),"") | M13: =IFERROR(IF(K13=0,"",K13/L13),"") | P13: =IFERROR(IF(N13=0,"",N13/O13),"") | S13: =IFERROR(IF(Q13=0,"",Q13/R13),"") | U13: =K13+N13+Q13 -> 0 | V13: =L13+O13+R13 -> 0 | W13: =IFERROR(U13/V13,"0") -> 0 | X13: =U13-T13 -> 0 | Y13: =IFERROR(U13/T13,"0") -> 0
C14: Total Sat | D14: =COUNTIF(I5:I35,"Sat") -> 4 | G14: 10 | H14: =IF(H13<$D$10,H13+1,"") -> 45757 | I14: =TEXT(H14,"DDD") -> Thu | J14: =IFERROR(VLOOKUP(H14,Sheet1!$A:$B,2,0),"") | M14: =IFERROR(IF(K14=0,"",K14/L14),"") | P14: =IFERROR(IF(N14=0,"",N14/O14),"") | S14: =IFERROR(IF(Q14=0,"",Q14/R14),"") | U14: =K14+N14+Q14 -> 0 | V14: =L14+O14+R14 -> 0 | W14: =IFERROR(U14/V14,"0") -> 0 | X14: =U14-T14 -> 0 | Y14: =IFERROR(U14/T14,"0") -> 0
C15: Total Sun | D15: =COUNTIF(I5:I35,"Sun") -> 4 | G15: 11 | H15: =IF(H14<$D$10,H14+1,"") -> 45758 | I15: =TEXT(H15,"DDD") -> Fri | J15: =IFERROR(VLOOKUP(H15,Sheet1!$A:$B,2,0),"") | M15: =IFERROR(IF(K15=0,"",K15/L15),"") | P15: =IFERROR(IF(N15=0,"",N15/O15),"") | S15: =IFERROR(IF(Q15=0,"",Q15/R15),"") | U15: =K15+N15+Q15 -> 0 | V15: =L15+O15+R15 -> 0 | W15: =IFERROR(U15/V15,"0") -> 0 | X15: =U15-T15 -> 0 | Y15: =IFERROR(U15/T15,"0") -> 0
G16: 12 | H16: =IF(H15<$D$10,H15+1,"") -> 45759 | I16: =TEXT(H16,"DDD") -> Sat | J16: =IFERROR(VLOOKUP(H16,Sheet1!$A:$B,2,0),"") | M16: =IFERROR(IF(K16=0,"",K16/L16),"") | P16: =IFERROR(IF(N16=0,"",N16/O16),"") | S16: =IFERROR(IF(Q16=0,"",Q16/R16),"") | U16: =K16+N16+Q16 -> 0 | V16: =L16+O16+R16 -> 0 | W16: =IFERROR(U16/V16,"0") -> 0 | X16: =U16-T16 -> 0 | Y16: =IFERROR(U16/T16,"0") -> 0
C17: Highest Sale for the month | D17: =MAX(U5:U35) -> 0 | G17: 13 | H17: =IF(H16<$D$10,H16+1,"") -> 45760 | I17: =TEXT(H17,"DDD") -> Sun | J17: =IFERROR(VLOOKUP(H17,Sheet1!$A:$B,2,0),"") | M17: =IFERROR(IF(K17=0,"",K17/L17),"") | P17: =IFERROR(IF(N17=0,"",N17/O17),"") | S17: =IFERROR(IF(Q17=0,"",Q17/R17),"") | U17: =K17+N17+Q17 -> 0 | V17: =L17+O17+R17 -> 0 | W17: =IFERROR(U17/V17,"0") -> 0 | X17: =U17-T17 -> 0 | Y17: =IFERROR(U17/T17,"0") -> 0
G18: 14 | H18: =IF(H17<$D$10,H17+1,"") -> 45761 | I18: =TEXT(H18,"DDD") -> Mon | J18: =IFERROR(VLOOKUP(H18,Sheet1!$A:$B,2,0),"") | M18: =IFERROR(IF(K18=0,"",K18/L18),"") | P18: =IFERROR(IF(N18=0,"",N18/O18),"") | S18: =IFERROR(IF(Q18=0,"",Q18/R18),"") | U18: =K18+N18+Q18 -> 0 | V18: =L18+O18+R18 -> 0 | W18: =IFERROR(U18/V18,"0") -> 0 | X18: =U18-T18 -> 0 | Y18: =IFERROR(U18/T18,"0") -> 0
G19: 15 | H19: =IF(H18<$D$10,H18+1,"") -> 45762 | I19: =TEXT(H19,"DDD") -> Tue | J19: =IFERROR(VLOOKUP(H19,Sheet1!$A:$B,2,0),"") | M19: =IFERROR(IF(K19=0,"",K19/L19),"") | P19: =IFERROR(IF(N19=0,"",N19/O19),"") | S19: =IFERROR(IF(Q19=0,"",Q19/R19),"") | U19: =K19+N19+Q19 -> 0 | V19: =L19+O19+R19 -> 0 | W19: =IFERROR(U19/V19,"0") -> 0 | X19: =U19-T19 -> 0 | Y19: =IFERROR(U19/T19,"0") -> 0
C20: Lowest Sale for the month | D20: =MIN(U8:U38) -> 0 | G20: 16 | H20: =IF(H19<$D$10,H19+1,"") -> 45763 | I20: =TEXT(H20,"DDD") -> Wed | J20: =IFERROR(VLOOKUP(H20,Sheet1!$A:$B,2,0),"") | M20: =IFERROR(IF(K20=0,"",K20/L20),"") | P20: =IFERROR(IF(N20=0,"",N20/O20),"") | S20: =IFERROR(IF(Q20=0,"",Q20/R20),"") | U20: =K20+N20+Q20 -> 0 | V20: =L20+O20+R20 -> 0 | W20: =IFERROR(U20/V20,"0") -> 0 | X20: =U20-T20 -> 0 | Y20: =IFERROR(U20/T20,"0") -> 0
G21: 17 | H21: =IF(H20<$D$10,H20+1,"") -> 45764 | I21: =TEXT(H21,"DDD") -> Thu | J21: =IFERROR(VLOOKUP(H21,Sheet1!$A:$B,2,0),"") | M21: =IFERROR(IF(K21=0,"",K21/L21),"") | P21: =IFERROR(IF(N21=0,"",N21/O21),"") | S21: =IFERROR(IF(Q21=0,"",Q21/R21),"") | U21: =K21+N21+Q21 -> 0 | V21: =L21+O21+R21 -> 0 | W21: =IFERROR(U21/V21,"0") -> 0 | X21: =U21-T21 -> 0 | Y21: =IFERROR(U21/T21,"0") -> 0
G22: 18 | H22: =IF(H21<$D$10,H21+1,"") -> 45765 | I22: =TEXT(H22,"DDD") -> Fri | J22: =IFERROR(VLOOKUP(H22,Sheet1!$A:$B,2,0),"") | M22: =IFERROR(IF(K22=0,"",K22/L22),"") | P22: =IFERROR(IF(N22=0,"",N22/O22),"") | S22: =IFERROR(IF(Q22=0,"",Q22/R22),"") | U22: =K22+N22+Q22 -> 0 | V22: =L22+O22+R22 -> 0 | W22: =IFERROR(U22/V22,"0") -> 0 | X22: =U22-T22 -> 0 | Y22: =IFERROR(U22/T22,"0") -> 0
C23: Target Achieved | D23: =IF(U36>T36,"Yes","No") -> No | G23: 19 | H23: =IF(H22<$D$10,H22+1,"") -> 45766 | I23: =TEXT(H23,"DDD") -> Sat | J23: =IFERROR(VLOOKUP(H23,Sheet1!$A:$B,2,0),"") | M23: =IFERROR(IF(K23=0,"",K23/L23),"") | P23: =IFERROR(IF(N23=0,"",N23/O23),"") | S23: =IFERROR(IF(Q23=0,"",Q23/R23),"") | U23: =K23+N23+Q23 -> 0 | V23: =L23+O23+R23 -> 0 | W23: =IFERROR(U23/V23,"0") -> 0 | X23: =U23-T23 -> 0 | Y23: =IFERROR(U23/T23,"0") -> 0
G24: 20 | H24: =IF(H23<$D$10,H23+1,"") -> 45767 | I24: =TEXT(H24,"DDD") -> Sun | J24: =IFERROR(VLOOKUP(H24,Sheet1!$A:$B,2,0),"") | M24: =IFERROR(IF(K24=0,"",K24/L24),"") | P24: =IFERROR(IF(N24=0,"",N24/O24),"") | S24: =IFERROR(IF(Q24=0,"",Q24/R24),"") | U24: =K24+N24+Q24 -> 0 | V24: =L24+O24+R24 -> 0 | W24: =IFERROR(U24/V24,"0") -> 0 | X24: =U24-T24 -> 0 | Y24: =IFERROR(U24/T24,"0") -> 0
C25: Sales Till Date | D25: =U36 -> 0 | G25: 21 | H25: =IF(H24<$D$10,H24+1,"") -> 45768 | I25: =TEXT(H25,"DDD") -> Mon | J25: =IFERROR(VLOOKUP(H25,Sheet1!$A:$B,2,0),"") | M25: =IFERROR(IF(K25=0,"",K25/L25),"") | P25: =IFERROR(IF(N25=0,"",N25/O25),"") | S25: =IFERROR(IF(Q25=0,"",Q25/R25),"") | U25: =K25+N25+Q25 -> 0 | V25: =L25+O25+R25 -> 0 | W25: =IFERROR(U25/V25,"0") -> 0 | X25: =U25-T25 -> 0 | Y25: =IFERROR(U25/T25,"0") -> 0
G26: 22 | H26: =IF(H25<$D$10,H25+1,"") -> 45769 | I26: =TEXT(H26,"DDD") -> Tue | J26: =IFERROR(VLOOKUP(H26,Sheet1!$A:$B,2,0),"") | M26: =IFERROR(IF(K26=0,"",K26/L26),"") | P26: =IFERROR(IF(N26=0,"",N26/O26),"") | S26: =IFERROR(IF(Q26=0,"",Q26/R26),"") | U26: =K26+N26+Q26 -> 0 | V26: =L26+O26+R26 -> 0 | W26: =IFERROR(U26/V26,"0") -> 0 | X26: =U26-T26 -> 0 | Y26: =IFERROR(U26/T26,"0") -> 0
C27: Average Sales | D27: =IFERROR(AVERAGE(U5:U35),"0") -> 0 | G27: 23 | H27: =IF(H26<$D$10,H26+1,"") -> 45770 | I27: =TEXT(H27,"DDD") -> Wed | J27: =IFERROR(VLOOKUP(H27,Sheet1!$A:$B,2,0),"") | M27: =IFERROR(IF(K27=0,"",K27/L27),"") | P27: =IFERROR(IF(N27=0,"",N27/O27),"") | S27: =IFERROR(IF(Q27=0,"",Q27/R27),"") | U27: =K27+N27+Q27 -> 0 | V27: =L27+O27+R27 -> 0 | W27: =IFERROR(U27/V27,"0") -> 0 | X27: =U27-T27 -> 0 | Y27: =IFERROR(U27/T27,"0") -> 0
C28: Dine in Sales | D28: =K36 -> 0 | G28: 24 | H28: =IF(H27<$D$10,H27+1,"") -> 45771 | I28: =TEXT(H28,"DDD") -> Thu | J28: =IFERROR(VLOOKUP(H28,Sheet1!$A:$B,2,0),"") | M28: =IFERROR(IF(K28=0,"",K28/L28),"") | P28: =IFERROR(IF(N28=0,"",N28/O28),"") | S28: =IFERROR(IF(Q28=0,"",Q28/R28),"") | U28: =K28+N28+Q28 -> 0 | V28: =L28+O28+R28 -> 0 | W28: =IFERROR(U28/V28,"0") -> 0 | X28: =U28-T28 -> 0 | Y28: =IFERROR(U28/T28,"0") -> 0
C29: Takeaway Sales | D29: =N36 -> 0 | G29: 25 | H29: =IF(H28<$D$10,H28+1,"") -> 45772 | I29: =TEXT(H29,"DDD") -> Fri | J29: =IFERROR(VLOOKUP(H29,Sheet1!$A:$B,2,0),"") | M29: =IFERROR(IF(K29=0,"",K29/L29),"") | P29: =IFERROR(IF(N29=0,"",N29/O29),"") | S29: =IFERROR(IF(Q29=0,"",Q29/R29),"") | U29: =K29+N29+Q29 -> 0 | V29: =L29+O29+R29 -> 0 | W29: =IFERROR(U29/V29,"0") -> 0 | X29: =U29-T29 -> 0 | Y29: =IFERROR(U29/T29,"0") -> 0
C30: Delivery Sales | D30: =Q36 -> 0 | G30: 26 | H30: =IF(H29<$D$10,H29+1,"") -> 45773 | I30: =TEXT(H30,"DDD") -> Sat | J30: =IFERROR(VLOOKUP(H30,Sheet1!$A:$B,2,0),"") | M30: =IFERROR(IF(K30=0,"",K30/L30),"") | P30: =IFERROR(IF(N30=0,"",N30/O30),"") | S30: =IFERROR(IF(Q30=0,"",Q30/R30),"") | U30: =K30+N30+Q30 -> 0 | V30: =L30+O30+R30 -> 0 | W30: =IFERROR(U30/V30,"0") -> 0 | X30: =U30-T30 -> 0 | Y30: =IFERROR(U30/T30,"0") -> 0
G31: 27 | H31: =IF(H30<$D$10,H30+1,"") -> 45774 | I31: =TEXT(H31,"DDD") -> Sun | J31: =IFERROR(VLOOKUP(H31,Sheet1!$A:$B,2,0),"") | M31: =IFERROR(IF(K31=0,"",K31/L31),"") | P31: =IFERROR(IF(N31=0,"",N31/O31),"") | S31: =IFERROR(IF(Q31=0,"",Q31/R31),"") | U31: =K31+N31+Q31 -> 0 | V31: =L31+O31+R31 -> 0 | W31: =IFERROR(U31/V31,"0") -> 0 | X31: =U31-T31 -> 0 | Y31: =IFERROR(U31/T31,"0") -> 0
C32: Total Sales | D32: =SUM(D28:D30) -> 0 | G32: 28 | H32: =IF(H31<$D$10,H31+1,"") -> 45775 | I32: =TEXT(H32,"DDD") -> Mon | J32: =IFERROR(VLOOKUP(H32,Sheet1!$A:$B,2,0),"") | M32: =IFERROR(IF(K32=0,"",K32/L32),"") | P32: =IFERROR(IF(N32=0,"",N32/O32),"") | S32: =IFERROR(IF(Q32=0,"",Q32/R32),"") | U32: =K32+N32+Q32 -> 0 | V32: =L32+O32+R32 -> 0 | W32: =IFERROR(U32/V32,"0") -> 0 | X32: =U32-T32 -> 0 | Y32: =IFERROR(U32/T32,"0") -> 0
C33: Last year sales | D33: 5000 | G33: 29 | H33: =IF(H32<$D$10,H32+1,"") -> 45776 | I33: =TEXT(H33,"DDD") -> Tue | J33: =IFERROR(VLOOKUP(H33,Sheet1!$A:$B,2,0),"") | M33: =IFERROR(IF(K33=0,"",K33/L33),"") | P33: =IFERROR(IF(N33=0,"",N33/O33),"") | S33: =IFERROR(IF(Q33=0,"",Q33/R33),"") | U33: =K33+N33+Q33 -> 0 | V33: =L33+O33+R33 -> 0 | W33: =IFERROR(U33/V33,"0") -> 0 | X33: =U33-T33 -> 0 | Y33: =IFERROR(U33/T33,"0") -> 0
C34: Growth | D34: =D32-D33 -> -5000 | G34: 30 | H34: =IF(H33<$D$10,H33+1,"") -> 45777 | I34: =TEXT(H34,"DDD") -> Wed | J34: =IFERROR(VLOOKUP(H34,Sheet1!$A:$B,2,0),"") | M34: =IFERROR(IF(K34=0,"",K34/L34),"") | P34: =IFERROR(IF(N34=0,"",N34/O34),"") | S34: =IFERROR(IF(Q34=0,"",Q34/R34),"") | U34: =K34+N34+Q34 -> 0 | V34: =L34+O34+R34 -> 0 | W34: =IFERROR(U34/V34,"0") -> 0 | X34: =U34-T34 -> 0 | Y34: =IFERROR(U34/T34,"0") -> 0
C35: Growth % | D35: =IFERROR((D32-D33)/D33,"0") -> -1 | G35: 31 | H35: =IF(H34<$D$10,H34+1,"") | I35: =TEXT(H35,"DDD") | J35: =IFERROR(VLOOKUP(H35,Sheet1!$A:$B,2,0),"") | M35: =IFERROR(IF(K35=0,"",K35/L35),"") | P35: =IFERROR(IF(N35=0,"",N35/O35),"") | S35: =IFERROR(IF(Q35=0,"",Q35/R35),"") | U35: =K35+N35+Q35 -> 0 | V35: =L35+O35+R35 -> 0 | W35: =IFERROR(U35/V35,"0") -> 0 | X35: =U35-T35 -> 0 | Y35: =IFERROR(U35/T35,"0") -> 0
G36: Total | K36: =SUM(K5:K35) -> 0 | L36: =SUM(L5:L35) -> 0 | M36: =IFERROR(K36/L36,"0") -> 0 | N36: =SUM(N5:N35) -> 0 | O36: =SUM(O5:O35) -> 0 | P36: =IFERROR(N36/O36,"0") -> 0 | Q36: =SUM(Q5:Q35) -> 0 | R36: =SUM(R5:R35) -> 0 | S36: =IFERROR(Q36/R36,"0") -> 0 | T36: =SUM(T5:T35) -> 0 | U36: =SUM(U5:U35) -> 0 | V36: =SUM(V5:V35) -> 0 | W36: =IFERROR(U36/V36,"0") -> 0 | X36: =SUM(X5:X35) -> 0 | Y36: =SUM(Y5:Y35) -> 0

Sheet May
B2: Summary
G3: Daily Sales Report | T3: Consolidated
C4: Month | D4: May | G4: Sr No. | H4: Date | I4: Day | J4: Holidays | K4: Dine in Sales | L4: Dine in Tkts. | M4: APC/APT(Avg. /Transaction) | N4: TA Sales | O4: TA Tkts. | P4: APC/APT(Avg. /Transaction) | Q4: Delivery Sales | R4: Delivery Tkts. | S4: APC/APT(Avg. /Transaction) | T4: Target Sales | U4: Total Sales | V4: Total Tkts. | W4: APC/APT | X4: Target vs Acheived | Y4: %
G5: 1 | H5: =D8 -> 45778 | I5: =TEXT(H5,"DDD") -> Thu | J5: =IFERROR(VLOOKUP(H5,Sheet1!$A:$B,2,0),"") -> Labour Day | M5: =IFERROR(IF(K5=0,"",K5/L5),"") | P5: =IFERROR(IF(N5=0,"",N5/O5),"") | S5: =IFERROR(IF(Q5=0,"",Q5/R5),"") | U5: =K5+N5+Q5 -> 0 | V5: =L5+O5+R5 -> 0 | W5: =IFERROR(U5/V5,"0") -> 0 | X5: =U5-T5 -> 0 | Y5: =IFERROR(U5/T5,"0") -> 0
C6: Year | D6: 2025 | G6: 2 | H6: =IF(H5<$D$10,H5+1,"") -> 45779 | I6: =TEXT(H6,"DDD") -> Fri | J6: =IFERROR(VLOOKUP(H6,Sheet1!$A:$B,2,0),"") | M6: =IFERROR(IF(K6=0,"",K6/L6),"") | P6: =IFERROR(IF(N6=0,"",N6/O6),"") | S6: =IFERROR(IF(Q6=0,"",Q6/R6),"") | U6: =K6+N6+Q6 -> 0 | V6: =L6+O6+R6 -> 0 | W6: =IFERROR(U6/V6,"0") -> 0 | X6: =U6-T6 -> 0 | Y6: =IFERROR(U6/T6,"0") -> 0
G7: 3 | H7: =IF(H6<$D$10,H6+1,"") -> 45780 | I7: =TEXT(H7,"DDD") -> Sat | J7: =IFERROR(VLOOKUP(H7,Sheet1!$A:$B,2,0),"") | M7: =IFERROR(IF(K7=0,"",K7/L7),"") | P7: =IFERROR(IF(N7=0,"",N7/O7),"") | S7: =IFERROR(IF(Q7=0,"",Q7/R7),"") | U7: =K7+N7+Q7 -> 0 | V7: =L7+O7+R7 -> 0 | W7: =IFERROR(U7/V7,"0") -> 0 | X7: =U7-T7 -> 0 | Y7: =IFERROR(U7/T7,"0") -> 0
C8: Start Date | D8: =DATEVALUE("01"&D4&D6) -> 45778 | G8: 4 | H8: =IF(H7<$D$10,H7+1,"") -> 45781 | I8: =TEXT(H8,"DDD") -> Sun | J8: =IFERROR(VLOOKUP(H8,Sheet1!$A:$B,2,0),"") | M8: =IFERROR(IF(K8=0,"",K8/L8),"") | P8: =IFERROR(IF(N8=0,"",N8/O8),"") | S8: =IFERROR(IF(Q8=0,"",Q8/R8),"") | U8: =K8+N8+Q8 -> 0 | V8: =L8+O8+R8 -> 0 | W8: =IFERROR(U8/V8,"0") -> 0 | X8: =U8-T8 -> 0 | Y8: =IFERROR(U8/T8,"0") -> 0
G9: 5 | H9: =IF(H8<$D$10,H8+1,"") -> 45782 | I9: =TEXT(H9,"DDD") -> Mon | J9: =IFERROR(VLOOKUP(H9,Sheet1!$A:$B,2,0),"") | M9: =IFERROR(IF(K9=0,"",K9/L9),"") | P9: =IFERROR(IF(N9=0,"",N9/O9),"") | S9: =IFERROR(IF(Q9=0,"",Q9/R9),"") | U9: =K9+N9+Q9 -> 0 | V9: =L9+O9+R9 -> 0 | W9: =IFERROR(U9/V9,"0") -> 0 | X9: =U9-T9 -> 0 | Y9: =IFERROR(U9/T9,"0") -> 0
C10: End Date | D10: =EOMONTH(D8,0) -> 45808 | G10: 6 | H10: =IF(H9<$D$10,H9+1,"") -> 45783 | I10: =TEXT(H10,"DDD") -> Tue | J10: =IFERROR(VLOOKUP(H10,Sheet1!$A:$B,2,0),"") | M10: =IFERROR(IF(K10=0,"",K10/L10),"") | P10: =IFERROR(IF(N10=0,"",N10/O10),"") | S10: =IFERROR(IF(Q10=0,"",Q10/R10),"") | U10: =K10+N10+Q10 -> 0 | V10: =L10+O10+R10 -> 0 | W10: =IFERROR(U10/V10,"0") -> 0 | X10: =U10-T10 -> 0 | Y10: =IFERROR(U10/T10,"0") -> 0
G11: 7 | H11: =IF(H10<$D$10,H10+1,"") -> 45784 | I11: =TEXT(H11,"DDD") -> Wed | J11: =IFERROR(VLOOKUP(H11,Sheet1!$A:$B,2,0),"") | M11: =IFERROR(IF(K11=0,"",K11/L11),"") | P11: =IFERROR(IF(N11=0,"",N11/O11),"") | S11: =IFERROR(IF(Q11=0,"",Q11/R11),"") | U11: =K11+N11+Q11 -> 0 | V11: =L11+O11+R11 -> 0 | W11: =IFERROR(U11/V11,"0") -> 0 | X11: =U11-T11 -> 0 | Y11: =IFERROR(U11/T11,"0") -> 0
C12: Total Days | D12: =COUNT(H5:H35) -> 31 | G12: 8 | H12: =IF(H11<$D$10,H11+1,"") -> 45785 | I12: =TEXT(H12,"DDD") -> Thu | J12: =IFERROR(VLOOKUP(H12,Sheet1!$A:$B,2,0),"") | M12: =IFERROR(IF(K12=0,"",K12/L12),"") | P12: =IFERROR(IF(N12=0,"",N12/O12),"") | S12: =IFERROR(IF(Q12=0,"",Q12/R12),"") | U12: =K12+N12+Q12 -> 0 | V12: =L12+O12+R12 -> 0 | W12: =IFERROR(U12/V12,"0") -> 0 | X12: =U12-T12 -> 0 | Y12: =IFERROR(U12/T12,"0") -> 0
G13: 9 | H13: =IF(H12<$D$10,H12+1,"") -> 45786 | I13: =TEXT(H13,"DDD") -> Fri | J13: =IFERROR(VLOOKUP(H13,Sheet1!$A:$B,2,0),"") | M13: =IFERROR(IF(K13=0,"",K13/L13),"") | P13: =IFERROR(IF(N13=0,"",N13/O13),"") | S13: =IFERROR(IF(Q13=0,"",Q13/R13),"") | U13: =K13+N13+Q13 -> 0 | V13: =L13+O13+R13 -> 0 | W13: =IFERROR(U13/V13,"0") -> 0 | X13: =U13-T13 -> 0 | Y13: =IFERROR(U13/T13,"0") -> 0
C14: Total Sat | D14: =COUNTIF(I5:I35,"Sat") -> 5 | G14: 10 | H14: =IF(H13<$D$10,H13+1,"") -> 45787 | I14: =TEXT(H14,"DDD") -> Sat | J14: =IFERROR(VLOOKUP(H14,Sheet1!$A:$B,2,0),"") | M14: =IFERROR(IF(K14=0,"",K14/L14),"") | P14: =IFERROR(IF(N14=0,"",N14/O14),"") | S14: =IFERROR(IF(Q14=0,"",Q14/R14),"") | U14: =K14+N14+Q14 -> 0 | V14: =L14+O14+R14 -> 0 | W14: =IFERROR(U14/V14,"0") -> 0 | X14: =U14-T14 -> 0 | Y14: =IFERROR(U14/T14,"0") -> 0
